Workbook

Sheet Tópicos
A1: Tópicos do curso — numeração baseada nas listas
A3: Código | B3: Tópico | C3: Categoria | E3: Rótulo completo
A4: 01 | B4: Contas Nacionais | C4: Lista | E4: 01 — Contas Nacionais
A5: 02 | B5: Balanço de Pagamentos | C5: Lista | E5: 02 — Balanço de Pagamentos
A6: 03 | B6: Sistema Monetário | C6: Lista | E6: 03 — Sistema Monetário
A7: 04 | B7: Demanda por Moeda | C7: Lista | E7: 04 — Demanda por Moeda
A8: 05 | B8: IS-LM | C8: Lista | E8: 05 — IS-LM
A9: 06 | B9: IS-LM-BP | C9: Lista | E9: 06 — IS-LM-BP
A10: 07a | B10: Paridades | C10: Lista | E10: 07a — Paridades
A11: 07b | B11: OA-DA | C11: Lista | E11: 07b — OA-DA
A12: 08 | B12: Curva de Phillips | C12: Lista | E12: 08 — Curva de Phillips
A13: 09 | B13: Expectativas, Novos Clássicos e Novos Keynesianos | C13: Lista | E13: 09 — Expectativas, Novos Clássicos e Novos Keynesianos
A14: 10 | B14: Ciclos Reais de Negócios (RBC) | C14: Lista | E14: 10 — Ciclos Reais de Negócios (RBC)
... A20: E2 | B20: Demanda de Bens e Complementaridade | C20: Extra | E20: E2 — Demanda de Bens e Complementaridade
A25: Taxonomia atualizada: 07a separa Paridades; 07b separa OA-DA. E1, E2, E3 e E5 foram incorporados conforme a metodologia.

Sheet Matriz
A1: Quantidade de itens equivalentes por tópico e prova — ANPEC Macro 2010–2026
A2: Levantamento item a item concluído: 17 provas, 2010–2026. Valores em itens equivalentes; confira a aba Validação.
A3: Tópico | B3: 2010 | C3: 2011 | D3: 2012 | E3: 2013 | F3: 2014 | G3: 2015 | H3: 2016 | I3: 2017 | J3: 2018 | K3: 2019 | L3: 2020 | M3: 2021 | N3: 2022 | O3: 2023 | P3: 2024 | Q3: 2025 | R3: 2026 | S3: Total
A4: 01 — Contas Nacionais | B4: =SUMIFS(Base_Itens!$I$5:$I$1504,Base_Itens!$A$5:$A$1504,B$3,Base_Itens!$G$5:$G$1504,$A4) -> 10 | C4: =SUMIFS(Base_Itens!$I$5:$I$1504,Base_Itens!$A$5:$A$1504,C$3,Base_Itens!$G$5:$G$1504,$A4) -> 5 | D4: =SUMIFS(Base_Itens!$I$5:$I$1504,Base_Itens!$A$5:$A$1504,D$3,Base_Itens!$G$5:$G$1504,$A4) -> 1 | E4: =SUMIFS(Base_Itens!$I$5:$I$1504,Base_Itens!$A$5:$A$1504,E$3,Base_Itens!$G$5:$G$1504,$A4) -> 7.5 | F4: =SUMIFS(Base_Itens!$I$5:$I$1504,Base_Itens!$A$5:$A$1504,F$3,Base_Itens!$G$5:$G$1504,$A4) -> 4 | G4: =SUMIFS(Base_Itens!$I$5:$I$1504,Base_Itens!$A$5:$A$1504,G$3,Base_Itens!$G$5:$G$1504,$A4) -> 5 | H4: =SUMIFS(Base_Itens!$I$5:$I$1504,Base_Itens!$A$5:$A$1504,H$3,Base_Itens!$G$5:$G$1504,$A4) -> 4 | I4: =SUMIFS(Base_Itens!$I$5:$I$1504,Base_Itens!$A$5:$A$1504,I$3,Base_Itens!$G$5:$G$1504,$A4) -> 8 | ... R4: =SUMIFS(Base_Itens!$I$5:$I$1504,Base_Itens!$A$5:$A$1504,R$3,Base_Itens!$G$5:$G$1504,$A4) -> 4 | S4: =SUM(B4:R4) -> 87.5
A5: 02 — Balanço de Pagamentos | B5: =SUMIFS(Base_Itens!$I$5:$I$1504,Base_Itens!$A$5:$A$1504,B$3,Base_Itens!$G$5:$G$1504,$A5) -> 0 | C5: =SUMIFS(Base_Itens!$I$5:$I$1504,Base_Itens!$A$5:$A$1504,C$3,Base_Itens!$G$5:$G$1504,$A5) -> 5 | D5: =SUMIFS(Base_Itens!$I$5:$I$1504,Base_Itens!$A$5:$A$1504,D$3,Base_Itens!$G$5:$G$1504,$A5) -> 4 | E5: =SUMIFS(Base_Itens!$I$5:$I$1504,Base_Itens!$A$5:$A$1504,E$3,Base_Itens!$G$5:$G$1504,$A5) -> 4.5 | F5: =SUMIFS(Base_Itens!$I$5:$I$1504,Base_Itens!$A$5:$A$1504,F$3,Base_Itens!$G$5:$G$1504,$A5) -> 1 | G5: =SUMIFS(Base_Itens!$I$5:$I$1504,Base_Itens!$A$5:$A$1504,G$3,Base_Itens!$G$5:$G$1504,$A5) -> 6 | H5: =SUMIFS(Base_Itens!$I$5:$I$1504,Base_Itens!$A$5:$A$1504,H$3,Base_Itens!$G$5:$G$1504,$A5) -> 5 | I5: =SUMIFS(Base_Itens!$I$5:$I$1504,Base_Itens!$A$5:$A$1504,I$3,Base_Itens!$G$5:$G$1504,$A5) -> 2 | ... R5: =SUMIFS(Base_Itens!$I$5:$I$1504,Base_Itens!$A$5:$A$1504,R$3,Base_Itens!$G$5:$G$1504,$A5) -> 5 | S5: =SUM(B5:R5) -> 61.5
A6: 03 — Sistema Monetário | B6: =SUMIFS(Base_Itens!$I$5:$I$1504,Base_Itens!$A$5:$A$1504,B$3,Base_Itens!$G$5:$G$1504,$A6) -> 7.6666667 | C6: =SUMIFS(Base_Itens!$I$5:$I$1504,Base_Itens!$A$5:$A$1504,C$3,Base_Itens!$G$5:$G$1504,$A6) -> 5 | D6: =SUMIFS(Base_Itens!$I$5:$I$1504,Base_Itens!$A$5:$A$1504,D$3,Base_Itens!$G$5:$G$1504,$A6) -> 8 | E6: =SUMIFS(Base_Itens!$I$5:$I$1504,Base_Itens!$A$5:$A$1504,E$3,Base_Itens!$G$5:$G$1504,$A6) -> 4 | F6: =SUMIFS(Base_Itens!$I$5:$I$1504,Base_Itens!$A$5:$A$1504,F$3,Base_Itens!$G$5:$G$1504,$A6) -> 4 | G6: =SUMIFS(Base_Itens!$I$5:$I$1504,Base_Itens!$A$5:$A$1504,G$3,Base_Itens!$G$5:$G$1504,$A6) -> 2 | H6: =SUMIFS(Base_Itens!$I$5:$I$1504,Base_Itens!$A$5:$A$1504,H$3,Base_Itens!$G$5:$G$1504,$A6) -> 5 | I6: =SUMIFS(Base_Itens!$I$5:$I$1504,Base_Itens!$A$5:$A$1504,I$3,Base_Itens!$G$5:$G$1504,$A6) -> 6 | ... R6: =SUMIFS(Base_Itens!$I$5:$I$1504,Base_Itens!$A$5:$A$1504,R$3,Base_Itens!$G$5:$G$1504,$A6) -> 2.5 | S6: =SUM(B6:R6) -> 69.666667
A7: 04 — Demanda por Moeda | B7: =SUMIFS(Base_Itens!$I$5:$I$1504,Base_Itens!$A$5:$A$1504,B$3,Base_Itens!$G$5:$G$1504,$A7) -> 2.1666667 | C7: =SUMIFS(Base_Itens!$I$5:$I$1504,Base_Itens!$A$5:$A$1504,C$3,Base_Itens!$G$5:$G$1504,$A7) -> 3 | D7: =SUMIFS(Base_Itens!$I$5:$I$1504,Base_Itens!$A$5:$A$1504,D$3,Base_Itens!$G$5:$G$1504,$A7) -> 5 | E7: =SUMIFS(Base_Itens!$I$5:$I$1504,Base_Itens!$A$5:$A$1504,E$3,Base_Itens!$G$5:$G$1504,$A7) -> 4 | F7: =SUMIFS(Base_Itens!$I$5:$I$1504,Base_Itens!$A$5:$A$1504,F$3,Base_Itens!$G$5:$G$1504,$A7) -> 2 | G7: =SUMIFS(Base_Itens!$I$5:$I$1504,Base_Itens!$A$5:$A$1504,G$3,Base_Itens!$G$5:$G$1504,$A7) -> 3 | H7: =SUMIFS(Base_Itens!$I$5:$I$1504,Base_Itens!$A$5:$A$1504,H$3,Base_Itens!$G$5:$G$1504,$A7) -> 1 | I7: =SUMIFS(Base_Itens!$I$5:$I$1504,Base_Itens!$A$5:$A$1504,I$3,Base_Itens!$G$5:$G$1504,$A7) -> 0 | ... R7: =SUMIFS(Base_Itens!$I$5:$I$1504,Base_Itens!$A$5:$A$1504,R$3,Base_Itens!$G$5:$G$1504,$A7) -> 2.5 | S7: =SUM(B7:R7) -> 40.666667
A8: 05 — IS-LM | B8: =SUMIFS(Base_Itens!$I$5:$I$1504,Base_Itens!$A$5:$A$1504,B$3,Base_Itens!$G$5:$G$1504,$A8) -> 9 | C8: =SUMIFS(Base_Itens!$I$5:$I$1504,Base_Itens!$A$5:$A$1504,C$3,Base_Itens!$G$5:$G$1504,$A8) -> 10 | D8: =SUMIFS(Base_Itens!$I$5:$I$1504,Base_Itens!$A$5:$A$1504,D$3,Base_Itens!$G$5:$G$1504,$A8) -> 5 | E8: =SUMIFS(Base_Itens!$I$5:$I$1504,Base_Itens!$A$5:$A$1504,E$3,Base_Itens!$G$5:$G$1504,$A8) -> 5 | F8: =SUMIFS(Base_Itens!$I$5:$I$1504,Base_Itens!$A$5:$A$1504,F$3,Base_Itens!$G$5:$G$1504,$A8) -> 4 | G8: =SUMIFS(Base_Itens!$I$5:$I$1504,Base_Itens!$A$5:$A$1504,G$3,Base_Itens!$G$5:$G$1504,$A8) -> 6.5 | H8: =SUMIFS(Base_Itens!$I$5:$I$1504,Base_Itens!$A$5:$A$1504,H$3,Base_Itens!$G$5:$G$1504,$A8) -> 8 | I8: =SUMIFS(Base_Itens!$I$5:$I$1504,Base_Itens!$A$5:$A$1504,I$3,Base_Itens!$G$5:$G$1504,$A8) -> 5 | ... R8: =SUMIFS(Base_Itens!$I$5:$I$1504,Base_Itens!$A$5:$A$1504,R$3,Base_Itens!$G$5:$G$1504,$A8) -> 2.5 | S8: =SUM(B8:R8) -> 74.5
A9: 06 — IS-LM-BP | B9: =SUMIFS(Base_Itens!$I$5:$I$1504,Base_Itens!$A$5:$A$1504,B$3,Base_Itens!$G$5:$G$1504,$A9) -> 7 | C9: =SUMIFS(Base_Itens!$I$5:$I$1504,Base_Itens!$A$5:$A$1504,C$3,Base_Itens!$G$5:$G$1504,$A9) -> 5 | D9: =SUMIFS(Base_Itens!$I$5:$I$1504,Base_Itens!$A$5:$A$1504,D$3,Base_Itens!$G$5:$G$1504,$A9) -> 15 | E9: =SUMIFS(Base_Itens!$I$5:$I$1504,Base_Itens!$A$5:$A$1504,E$3,Base_Itens!$G$5:$G$1504,$A9) -> 5 | F9: =SUMIFS(Base_Itens!$I$5:$I$1504,Base_Itens!$A$5:$A$1504,F$3,Base_Itens!$G$5:$G$1504,$A9) -> 6 | G9: =SUMIFS(Base_Itens!$I$5:$I$1504,Base_Itens!$A$5:$A$1504,G$3,Base_Itens!$G$5:$G$1504,$A9) -> 5 | H9: =SUMIFS(Base_Itens!$I$5:$I$1504,Base_Itens!$A$5:$A$1504,H$3,Base_Itens!$G$5:$G$1504,$A9) -> 4.5 | I9: =SUMIFS(Base_Itens!$I$5:$I$1504,Base_Itens!$A$5:$A$1504,I$3,Base_Itens!$G$5:$G$1504,$A9) -> 10 | ... R9: =SUMIFS(Base_Itens!$I$5:$I$1504,Base_Itens!$A$5:$A$1504,R$3,Base_Itens!$G$5:$G$1504,$A9) -> 0 | S9: =SUM(B9:R9) -> 119.5
A10: 07a — Paridades | B10: =SUMIFS(Base_Itens!$I$5:$I$1504,Base_Itens!$A$5:$A$1504,B$3,Base_Itens!$G$5:$G$1504,$A10) -> 7.5 | C10: =SUMIFS(Base_Itens!$I$5:$I$1504,Base_Itens!$A$5:$A$1504,C$3,Base_Itens!$G$5:$G$1504,$A10) -> 5 | D10: =SUMIFS(Base_Itens!$I$5:$I$1504,Base_Itens!$A$5:$A$1504,D$3,Base_Itens!$G$5:$G$1504,$A10) -> 4 | E10: =SUMIFS(Base_Itens!$I$5:$I$1504,Base_Itens!$A$5:$A$1504,E$3,Base_Itens!$G$5:$G$1504,$A10) -> 11 | F10: =SUMIFS(Base_Itens!$I$5:$I$1504,Base_Itens!$A$5:$A$1504,F$3,Base_Itens!$G$5:$G$1504,$A10) -> 7 | G10: =SUMIFS(Base_Itens!$I$5:$I$1504,Base_Itens!$A$5:$A$1504,G$3,Base_Itens!$G$5:$G$1504,$A10) -> 6 | H10: =SUMIFS(Base_Itens!$I$5:$I$1504,Base_Itens!$A$5:$A$1504,H$3,Base_Itens!$G$5:$G$1504,$A10) -> 5.5 | I10: =SUMIFS(Base_Itens!$I$5:$I$1504,Base_Itens!$A$5:$A$1504,I$3,Base_Itens!$G$5:$G$1504,$A10) -> 0 | ... R10: =SUMIFS(Base_Itens!$I$5:$I$1504,Base_Itens!$A$5:$A$1504,R$3,Base_Itens!$G$5:$G$1504,$A10) -> 5 | S10: =SUM(B10:R10) -> 127
A11: 07b — OA-DA | B11: =SUMIFS(Base_Itens!$I$5:$I$1504,Base_Itens!$A$5:$A$1504,B$3,Base_Itens!$G$5:$G$1504,$A11) -> 2.5 | C11: =SUMIFS(Base_Itens!$I$5:$I$1504,Base_Itens!$A$5:$A$1504,C$3,Base_Itens!$G$5:$G$1504,$A11) -> 1 | D11: =SUMIFS(Base_Itens!$I$5:$I$1504,Base_Itens!$A$5:$A$1504,D$3,Base_Itens!$G$5:$G$1504,$A11) -> 1 | E11: =SUMIFS(Base_Itens!$I$5:$I$1504,Base_Itens!$A$5:$A$1504,E$3,Base_Itens!$G$5:$G$1504,$A11) -> 1 | F11: =SUMIFS(Base_Itens!$I$5:$I$1504,Base_Itens!$A$5:$A$1504,F$3,Base_Itens!$G$5:$G$1504,$A11) -> 1 | G11: =SUMIFS(Base_Itens!$I$5:$I$1504,Base_Itens!$A$5:$A$1504,G$3,Base_Itens!$G$5:$G$1504,$A11) -> 0 | H11: =SUMIFS(Base_Itens!$I$5:$I$1504,Base_Itens!$A$5:$A$1504,H$3,Base_Itens!$G$5:$G$1504,$A11) -> 4.5 | I11: =SUMIFS(Base_Itens!$I$5:$I$1504,Base_Itens!$A$5:$A$1504,I$3,Base_Itens!$G$5:$G$1504,$A11) -> 0.5 | ... R11: =SUMIFS(Base_Itens!$I$5:$I$1504,Base_Itens!$A$5:$A$1504,R$3,Base_Itens!$G$5:$G$1504,$A11) -> 2 | S11: =SUM(B11:R11) -> 35
A12: 08 — Curva de Phillips | B12: =SUMIFS(Base_Itens!$I$5:$I$1504,Base_Itens!$A$5:$A$1504,B$3,Base_Itens!$G$5:$G$1504,$A12) -> 7.5 | C12: =SUMIFS(Base_Itens!$I$5:$I$1504,Base_Itens!$A$5:$A$1504,C$3,Base_Itens!$G$5:$G$1504,$A12) -> 4 | D12: =SUMIFS(Base_Itens!$I$5:$I$1504,Base_Itens!$A$5:$A$1504,D$3,Base_Itens!$G$5:$G$1504,$A12) -> 5.5 | E12: =SUMIFS(Base_Itens!$I$5:$I$1504,Base_Itens!$A$5:$A$1504,E$3,Base_Itens!$G$5:$G$1504,$A12) -> 1 | F12: =SUMIFS(Base_Itens!$I$5:$I$1504,Base_Itens!$A$5:$A$1504,F$3,Base_Itens!$G$5:$G$1504,$A12) -> 7 | G12: =SUMIFS(Base_Itens!$I$5:$I$1504,Base_Itens!$A$5:$A$1504,G$3,Base_Itens!$G$5:$G$1504,$A12) -> 5 | H12: =SUMIFS(Base_Itens!$I$5:$I$1504,Base_Itens!$A$5:$A$1504,H$3,Base_Itens!$G$5:$G$1504,$A12) -> 3.5 | I12: =SUMIFS(Base_Itens!$I$5:$I$1504,Base_Itens!$A$5:$A$1504,I$3,Base_Itens!$G$5:$G$1504,$A12) -> 6.5 | ... R12: =SUMIFS(Base_Itens!$I$5:$I$1504,Base_Itens!$A$5:$A$1504,R$3,Base_Itens!$G$5:$G$1504,$A12) -> 1.5 | S12: =SUM(B12:R12) -> 81.5
A13: 09 — Expectativas, Novos Clássicos e Novos Keynesianos | B13: =SUMIFS(Base_Itens!$I$5:$I$1504,Base_Itens!$A$5:$A$1504,B$3,Base_Itens!$G$5:$G$1504,$A13) -> 6 | C13: =SUMIFS(Base_Itens!$I$5:$I$1504,Base_Itens!$A$5:$A$1504,C$3,Base_Itens!$G$5:$G$1504,$A13) -> 2 | D13: =SUMIFS(Base_Itens!$I$5:$I$1504,Base_Itens!$A$5:$A$1504,D$3,Base_Itens!$G$5:$G$1504,$A13) -> 9.5 | E13: =SUMIFS(Base_Itens!$I$5:$I$1504,Base_Itens!$A$5:$A$1504,E$3,Base_Itens!$G$5:$G$1504,$A13) -> 6 | F13: =SUMIFS(Base_Itens!$I$5:$I$1504,Base_Itens!$A$5:$A$1504,F$3,Base_Itens!$G$5:$G$1504,$A13) -> 14.5 | G13: =SUMIFS(Base_Itens!$I$5:$I$1504,Base_Itens!$A$5:$A$1504,G$3,Base_Itens!$G$5:$G$1504,$A13) -> 13.5 | H13: =SUMIFS(Base_Itens!$I$5:$I$1504,Base_Itens!$A$5:$A$1504,H$3,Base_Itens!$G$5:$G$1504,$A13) -> 5 | I13: =SUMIFS(Base_Itens!$I$5:$I$1504,Base_Itens!$A$5:$A$1504,I$3,Base_Itens!$G$5:$G$1504,$A13) -> 7 | ... R13: =SUMIFS(Base_Itens!$I$5:$I$1504,Base_Itens!$A$5:$A$1504,R$3,Base_Itens!$G$5:$G$1504,$A13) -> 12 | S13: =SUM(B13:R13) -> 144
A14: 10 — Ciclos Reais de Negócios (RBC) | B14: =SUMIFS(Base_Itens!$I$5:$I$1504,Base_Itens!$A$5:$A$1504,B$3,Base_Itens!$G$5:$G$1504,$A14) -> 1 | C14: =SUMIFS(Base_Itens!$I$5:$I$1504,Base_Itens!$A$5:$A$1504,C$3,Base_Itens!$G$5:$G$1504,$A14) -> 5 | D14: =SUMIFS(Base_Itens!$I$5:$I$1504,Base_Itens!$A$5:$A$1504,D$3,Base_Itens!$G$5:$G$1504,$A14) -> 0 | E14: =SUMIFS(Base_Itens!$I$5:$I$1504,Base_Itens!$A$5:$A$1504,E$3,Base_Itens!$G$5:$G$1504,$A14) -> 3 | F14: =SUMIFS(Base_Itens!$I$5:$I$1504,Base_Itens!$A$5:$A$1504,F$3,Base_Itens!$G$5:$G$1504,$A14) -> 0.5 | G14: =SUMIFS(Base_Itens!$I$5:$I$1504,Base_Itens!$A$5:$A$1504,G$3,Base_Itens!$G$5:$G$1504,$A14) -> 2 | H14: =SUMIFS(Base_Itens!$I$5:$I$1504,Base_Itens!$A$5:$A$1504,H$3,Base_Itens!$G$5:$G$1504,$A14) -> 2 | I14: =SUMIFS(Base_Itens!$I$5:$I$1504,Base_Itens!$A$5:$A$1504,I$3,Base_Itens!$G$5:$G$1504,$A14) -> 3 | ... R14: =SUMIFS(Base_Itens!$I$5:$I$1504,Base_Itens!$A$5:$A$1504,R$3,Base_Itens!$G$5:$G$1504,$A14) -> 1 | S14: =SUM(B14:R14) -> 22.5
A15: 11 — Crescimento Econômico | B15: =SUMIFS(Base_Itens!$I$5:$I$1504,Base_Itens!$A$5:$A$1504,B$3,Base_Itens!$G$5:$G$1504,$A15) -> 10 | C15: =SUMIFS(Base_Itens!$I$5:$I$1504,Base_Itens!$A$5:$A$1504,C$3,Base_Itens!$G$5:$G$1504,$A15) -> 10 | D15: =SUMIFS(Base_Itens!$I$5:$I$1504,Base_Itens!$A$5:$A$1504,D$3,Base_Itens!$G$5:$G$1504,$A15) -> 10 | E15: =SUMIFS(Base_Itens!$I$5:$I$1504,Base_Itens!$A$5:$A$1504,E$3,Base_Itens!$G$5:$G$1504,$A15) -> 10 | F15: =SUMIFS(Base_Itens!$I$5:$I$1504,Base_Itens!$A$5:$A$1504,F$3,Base_Itens!$G$5:$G$1504,$A15) -> 10 | G15: =SUMIFS(Base_Itens!$I$5:$I$1504,Base_Itens!$A$5:$A$1504,G$3,Base_Itens!$G$5:$G$1504,$A15) -> 10 | H15: =SUMIFS(Base_Itens!$I$5:$I$1504,Base_Itens!$A$5:$A$1504,H$3,Base_Itens!$G$5:$G$1504,$A15) -> 15 | I15: =SUMIFS(Base_Itens!$I$5:$I$1504,Base_Itens!$A$5:$A$1504,I$3,Base_Itens!$G$5:$G$1504,$A15) -> 10 | ... R15: =SUMIFS(Base_Itens!$I$5:$I$1504,Base_Itens!$A$5:$A$1504,R$3,Base_Itens!$G$5:$G$1504,$A15) -> 5 | S15: =SUM(B15:R15) -> 155
... A20: E2 — Demanda de Bens e Complementaridade | B20: =SUMIFS(Base_Itens!$I$5:$I$1504,Base_Itens!$A$5:$A$1504,B$3,Base_Itens!$G$5:$G$1504,$A20) -> 0 | C20: =SUMIFS(Base_Itens!$I$5:$I$1504,Base_Itens!$A$5:$A$1504,C$3,Base_Itens!$G$5:$G$1504,$A20) -> 0 | D20: =SUMIFS(Base_Itens!$I$5:$I$1504,Base_Itens!$A$5:$A$1504,D$3,Base_Itens!$G$5:$G$1504,$A20) -> 0 | E20: =SUMIFS(Base_Itens!$I$5:$I$1504,Base_Itens!$A$5:$A$1504,E$3,Base_Itens!$G$5:$G$1504,$A20) -> 0 | F20: =SUMIFS(Base_Itens!$I$5:$I$1504,Base_Itens!$A$5:$A$1504,F$3,Base_Itens!$G$5:$G$1504,$A20) -> 0 | G20: =SUMIFS(Base_Itens!$I$5:$I$1504,Base_Itens!$A$5:$A$1504,G$3,Base_Itens!$G$5:$G$1504,$A20) -> 0 | H20: =SUMIFS(Base_Itens!$I$5:$I$1504,Base_Itens!$A$5:$A$1504,H$3,Base_Itens!$G$5:$G$1504,$A20) -> 0 | I20: =SUMIFS(Base_Itens!$I$5:$I$1504,Base_Itens!$A$5:$A$1504,I$3,Base_Itens!$G$5:$G$1504,$A20) -> 0 | ... R20: =SUMIFS(Base_Itens!$I$5:$I$1504,Base_Itens!$A$5:$A$1504,R$3,Base_Itens!$G$5:$G$1504,$A20) -> 0 | S20: =SUM(B20:R20) -> 1
A25: TOTAL POR PROVA | B25: =SUM(B4:B20) -> 75 | C25: =SUM(C4:C20) -> 75 | D25: =SUM(D4:D20) -> 75 | E25: =SUM(E4:E20) -> 75 | F25: =SUM(F4:F20) -> 75 | G25: =SUM(G4:G20) -> 75 | H25: =SUM(H4:H20) -> 75 | I25: =SUM(I4:I20) -> 75 | ... S25: =SUM(S4:S20) -> 1200

Sheet Dashboard
A1: Dashboard — incidência de tópicos nas provas de Macroeconomia da ANPEC
A3: Ano selecionado | B3: 2026 | E3: Altere B3 para filtrar o gráfico de barras por ano. A Base_Itens alimenta automaticamente a matriz e os dois gráficos.
U5: Ano | V5: 01 — Contas Nacionais | W5: 02 — Balanço de Pagamentos | X5: 03 — Sistema Monetário | Y5: 04 — Demanda por Moeda | Z5: 05 — IS-LM | AA5: 06 — IS-LM-BP | AB5: 07a — Paridades | AC5: 07b — OA-DA | AD5: 08 — Curva de Phillips | AE5: 09 — Expectativas, Novos Clássicos e Novos Keynesianos | AF5: 10 — Ciclos Reais de Negócios (RBC) | AG5: 11 — Crescimento Econômico | AH5: 12 — Consumo | AI5: 13 — Investimento | AJ5: 14 — Dívida Pública e Senhoriagem | AK5: E1 — Mercados Financeiros | AL5: E2 — Demanda de Bens e Complementaridade | AM5: =Tópicos!E21 -> 0 | AN5: =Tópicos!E22 -> 0 | AO5: =Tópicos!E23 -> 0
A6: Tópico | B6: Quantidade | C6: (%) | U6: 2010 | V6: =IF($B$32="Sim",INDEX(Matriz!$B$4:$R$4,1,MATCH($U6,Matriz!$B$3:$R$3,0)),NA()) -> #N/A | W6: =IF($B$33="Sim",INDEX(Matriz!$B$5:$R$5,1,MATCH($U6,Matriz!$B$3:$R$3,0)),NA()) -> #N/A | X6: =IF($B$34="Sim",INDEX(Matriz!$B$6:$R$6,1,MATCH($U6,Matriz!$B$3:$R$3,0)),NA()) -> #N/A | Y6: =IF($B$35="Sim",INDEX(Matriz!$B$7:$R$7,1,MATCH($U6,Matriz!$B$3:$R$3,0)),NA()) -> #N/A | Z6: =IF($B$36="Sim",INDEX(Matriz!$B$8:$R$8,1,MATCH($U6,Matriz!$B$3:$R$3,0)),NA()) -> #N/A | AA6: =IF($B$37="Sim",INDEX(Matriz!$B$9:$R$9,1,MATCH($U6,Matriz!$B$3:$R$3,0)),NA()) -> 7 | AB6: =IF($B$38="Sim",INDEX(Matriz!$B$10:$R$10,1,MATCH($U6,Matriz!$B$3:$R$3,0)),NA()) -> #N/A | AC6: =IF($B$39="Sim",INDEX(Matriz!$B$11:$R$11,1,MATCH($U6,Matriz!$B$3:$R$3,0)),NA()) -> #N/A | AD6: =IF($B$40="Sim",INDEX(Matriz!$B$12:$R$12,1,MATCH($U6,Matriz!$B$3:$R$3,0)),NA()) -> #N/A | AE6: =IF($B$41="Sim",INDEX(Matriz!$B$13:$R$13,1,MATCH($U6,Matriz!$B$3:$R$3,0)),NA()) -> #N/A | AF6: =IF($B$42="Sim",INDEX(Matriz!$B$14:$R$14,1,MATCH($U6,Matriz!$B$3:$R$3,0)),NA()) -> #N/A | AG6: =IF($B$43="Sim",INDEX(Matriz!$B$15:$R$15,1,MATCH($U6,Matriz!$B$3:$R$3,0)),NA()) -> #N/A | AH6: =IF($B$44="Sim",INDEX(Matriz!$B$16:$R$16,1,MATCH($U6,Matriz!$B$3:$R$3,0)),NA()) -> #N/A | AI6: =IF($B$45="Sim",INDEX(Matriz!$B$17:$R$17,1,MATCH($U6,Matriz!$B$3:$R$3,0)),NA()) -> #N/A | AJ6: =IF($B$46="Sim",INDEX(Matriz!$B$18:$R$18,1,MATCH($U6,Matriz!$B$3:$R$3,0)),NA()) -> #N/A | AK6: =IF($B$47="Sim",INDEX(Matriz!$B$19:$R$19,1,MATCH($U6,Matriz!$B$3:$R$3,0)),NA()) -> #N/A | AL6: =IF($B$48="Sim",INDEX(Matriz!$B$20:$R$20,1,MATCH($U6,Matriz!$B$3:$R$3,0)),NA()) -> #N/A | AM6: =INDEX(Matriz!$B$21:$R$21,1,MATCH($U6,Matriz!$B$3:$R$3,0)) -> 0 | AN6: =INDEX(Matriz!$B$22:$R$22,1,MATCH($U6,Matriz!$B$3:$R$3,0)) -> 0 | AO6: =INDEX(Matriz!$B$23:$R$23,1,MATCH($U6,Matriz!$B$3:$R$3,0)) -> 0
A7: 01 — Contas Nacionais | B7: =INDEX(Matriz!$B$4:$R$4,1,MATCH(VALUE($B$3),Matriz!$B$3:$R$3,0)) -> 4 | C7: =B7/SUM($B$7:$B$23) -> 0.08 | U7: 2011 | V7: =IF($B$32="Sim",INDEX(Matriz!$B$4:$R$4,1,MATCH($U7,Matriz!$B$3:$R$3,0)),NA()) -> #N/A | W7: =IF($B$33="Sim",INDEX(Matriz!$B$5:$R$5,1,MATCH($U7,Matriz!$B$3:$R$3,0)),NA()) -> #N/A | X7: =IF($B$34="Sim",INDEX(Matriz!$B$6:$R$6,1,MATCH($U7,Matriz!$B$3:$R$3,0)),NA()) -> #N/A | Y7: =IF($B$35="Sim",INDEX(Matriz!$B$7:$R$7,1,MATCH($U7,Matriz!$B$3:$R$3,0)),NA()) -> #N/A | Z7: =IF($B$36="Sim",INDEX(Matriz!$B$8:$R$8,1,MATCH($U7,Matriz!$B$3:$R$3,0)),NA()) -> #N/A | AA7: =IF($B$37="Sim",INDEX(Matriz!$B$9:$R$9,1,MATCH($U7,Matriz!$B$3:$R$3,0)),NA()) -> 5 | AB7: =IF($B$38="Sim",INDEX(Matriz!$B$10:$R$10,1,MATCH($U7,Matriz!$B$3:$R$3,0)),NA()) -> #N/A | AC7: =IF($B$39="Sim",INDEX(Matriz!$B$11:$R$11,1,MATCH($U7,Matriz!$B$3:$R$3,0)),NA()) -> #N/A | AD7: =IF($B$40="Sim",INDEX(Matriz!$B$12:$R$12,1,MATCH($U7,Matriz!$B$3:$R$3,0)),NA()) -> #N/A | AE7: =IF($B$41="Sim",INDEX(Matriz!$B$13:$R$13,1,MATCH($U7,Matriz!$B$3:$R$3,0)),NA()) -> #N/A | AF7: =IF($B$42="Sim",INDEX(Matriz!$B$14:$R$14,1,MATCH($U7,Matriz!$B$3:$R$3,0)),NA()) -> #N/A | AG7: =IF($B$43="Sim",INDEX(Matriz!$B$15:$R$15,1,MATCH($U7,Matriz!$B$3:$R$3,0)),NA()) -> #N/A | AH7: =IF($B$44="Sim",INDEX(Matriz!$B$16:$R$16,1,MATCH($U7,Matriz!$B$3:$R$3,0)),NA()) -> #N/A | AI7: =IF($B$45="Sim",INDEX(Matriz!$B$17:$R$17,1,MATCH($U7,Matriz!$B$3:$R$3,0)),NA()) -> #N/A | AJ7: =IF($B$46="Sim",INDEX(Matriz!$B$18:$R$18,1,MATCH($U7,Matriz!$B$3:$R$3,0)),NA()) -> #N/A | AK7: =IF($B$47="Sim",INDEX(Matriz!$B$19:$R$19,1,MATCH($U7,Matriz!$B$3:$R$3,0)),NA()) -> #N/A | AL7: =IF($B$48="Sim",INDEX(Matriz!$B$20:$R$20,1,MATCH($U7,Matriz!$B$3:$R$3,0)),NA()) -> #N/A | AM7: =INDEX(Matriz!$B$21:$R$21,1,MATCH($U7,Matriz!$B$3:$R$3,0)) -> 0 | AN7: =INDEX(Matriz!$B$22:$R$22,1,MATCH($U7,Matriz!$B$3:$R$3,0)) -> 0 | AO7: =INDEX(Matriz!$B$23:$R$23,1,MATCH($U7,Matriz!$B$3:$R$3,0)) -> 0
A8: 02 — Balanço de Pagamentos | B8: =INDEX(Matriz!$B$5:$R$5,1,MATCH(VALUE($B$3),Matriz!$B$3:$R$3,0)) -> 5 | C8: =B8/SUM($B$7:$B$23) -> 0.1 | U8: 2012 | V8: =IF($B$32="Sim",INDEX(Matriz!$B$4:$R$4,1,MATCH($U8,Matriz!$B$3:$R$3,0)),NA()) -> #N/A | W8: =IF($B$33="Sim",INDEX(Matriz!$B$5:$R$5,1,MATCH($U8,Matriz!$B$3:$R$3,0)),NA()) -> #N/A | X8: =IF($B$34="Sim",INDEX(Matriz!$B$6:$R$6,1,MATCH($U8,Matriz!$B$3:$R$3,0)),NA()) -> #N/A | Y8: =IF($B$35="Sim",INDEX(Matriz!$B$7:$R$7,1,MATCH($U8,Matriz!$B$3:$R$3,0)),NA()) -> #N/A | Z8: =IF($B$36="Sim",INDEX(Matriz!$B$8:$R$8,1,MATCH($U8,Matriz!$B$3:$R$3,0)),NA()) -> #N/A | AA8: =IF($B$37="Sim",INDEX(Matriz!$B$9:$R$9,1,MATCH($U8,Matriz!$B$3:$R$3,0)),NA()) -> 15 | AB8: =IF($B$38="Sim",INDEX(Matriz!$B$10:$R$10,1,MATCH($U8,Matriz!$B$3:$R$3,0)),NA()) -> #N/A | AC8: =IF($B$39="Sim",INDEX(Matriz!$B$11:$R$11,1,MATCH($U8,Matriz!$B$3:$R$3,0)),NA()) -> #N/A | AD8: =IF($B$40="Sim",INDEX(Matriz!$B$12:$R$12,1,MATCH($U8,Matriz!$B$3:$R$3,0)),NA()) -> #N/A | AE8: =IF($B$41="Sim",INDEX(Matriz!$B$13:$R$13,1,MATCH($U8,Matriz!$B$3:$R$3,0)),NA()) -> #N/A | AF8: =IF($B$42="Sim",INDEX(Matriz!$B$14:$R$14,1,MATCH($U8,Matriz!$B$3:$R$3,0)),NA()) -> #N/A | AG8: =IF($B$43="Sim",INDEX(Matriz!$B$15:$R$15,1,MATCH($U8,Matriz!$B$3:$R$3,0)),NA()) -> #N/A | AH8: =IF($B$44="Sim",INDEX(Matriz!$B$16:$R$16,1,MATCH($U8,Matriz!$B$3:$R$3,0)),NA()) -> #N/A | AI8: =IF($B$45="Sim",INDEX(Matriz!$B$17:$R$17,1,MATCH($U8,Matriz!$B$3:$R$3,0)),NA()) -> #N/A | AJ8: =IF($B$46="Sim",INDEX(Matriz!$B$18:$R$18,1,MATCH($U8,Matriz!$B$3:$R$3,0)),NA()) -> #N/A | AK8: =IF($B$47="Sim",INDEX(Matriz!$B$19:$R$19,1,MATCH($U8,Matriz!$B$3:$R$3,0)),NA()) -> #N/A | AL8: =IF($B$48="Sim",INDEX(Matriz!$B$20:$R$20,1,MATCH($U8,Matriz!$B$3:$R$3,0)),NA()) -> #N/A | AM8: =INDEX(Matriz!$B$21:$R$21,1,MATCH($U8,Matriz!$B$3:$R$3,0)) -> 0 | AN8: =INDEX(Matriz!$B$22:$R$22,1,MATCH($U8,Matriz!$B$3:$R$3,0)) -> 0 | AO8: =INDEX(Matriz!$B$23:$R$23,1,MATCH($U8,Matriz!$B$3:$R$3,0)) -> 0
A9: 03 — Sistema Monetário | B9: =INDEX(Matriz!$B$6:$R$6,1,MATCH(VALUE($B$3),Matriz!$B$3:$R$3,0)) -> 2.5 | C9: =B9/SUM($B$7:$B$23) -> 0.05 | U9: 2013 | V9: =IF($B$32="Sim",INDEX(Matriz!$B$4:$R$4,1,MATCH($U9,Matriz!$B$3:$R$3,0)),NA()) -> #N/A | W9: =IF($B$33="Sim",INDEX(Matriz!$B$5:$R$5,1,MATCH($U9,Matriz!$B$3:$R$3,0)),NA()) -> #N/A | X9: =IF($B$34="Sim",INDEX(Matriz!$B$6:$R$6,1,MATCH($U9,Matriz!$B$3:$R$3,0)),NA()) -> #N/A | Y9: =IF($B$35="Sim",INDEX(Matriz!$B$7:$R$7,1,MATCH($U9,Matriz!$B$3:$R$3,0)),NA()) -> #N/A | Z9: =IF($B$36="Sim",INDEX(Matriz!$B$8:$R$8,1,MATCH($U9,Matriz!$B$3:$R$3,0)),NA()) -> #N/A | AA9: =IF($B$37="Sim",INDEX(Matriz!$B$9:$R$9,1,MATCH($U9,Matriz!$B$3:$R$3,0)),NA()) -> 5 | AB9: =IF($B$38="Sim",INDEX(Matriz!$B$10:$R$10,1,MATCH($U9,Matriz!$B$3:$R$3,0)),NA()) -> #N/A | AC9: =IF($B$39="Sim",INDEX(Matriz!$B$11:$R$11,1,MATCH($U9,Matriz!$B$3:$R$3,0)),NA()) -> #N/A | AD9: =IF($B$40="Sim",INDEX(Matriz!$B$12:$R$12,1,MATCH($U9,Matriz!$B$3:$R$3,0)),NA()) -> #N/A | AE9: =IF($B$41="Sim",INDEX(Matriz!$B$13:$R$13,1,MATCH($U9,Matriz!$B$3:$R$3,0)),NA()) -> #N/A | AF9: =IF($B$42="Sim",INDEX(Matriz!$B$14:$R$14,1,MATCH($U9,Matriz!$B$3:$R$3,0)),NA()) -> #N/A | AG9: =IF($B$43="Sim",INDEX(Matriz!$B$15:$R$15,1,MATCH($U9,Matriz!$B$3:$R$3,0)),NA()) -> #N/A | AH9: =IF($B$44="Sim",INDEX(Matriz!$B$16:$R$16,1,MATCH($U9,Matriz!$B$3:$R$3,0)),NA()) -> #N/A | AI9: =IF($B$45="Sim",INDEX(Matriz!$B$17:$R$17,1,MATCH($U9,Matriz!$B$3:$R$3,0)),NA()) -> #N/A | AJ9: =IF($B$46="Sim",INDEX(Matriz!$B$18:$R$18,1,MATCH($U9,Matriz!$B$3:$R$3,0)),NA()) -> #N/A | AK9: =IF($B$47="Sim",INDEX(Matriz!$B$19:$R$19,1,MATCH($U9,Matriz!$B$3:$R$3,0)),NA()) -> #N/A | AL9: =IF($B$48="Sim",INDEX(Matriz!$B$20:$R$20,1,MATCH($U9,Matriz!$B$3:$R$3,0)),NA()) -> #N/A | AM9: =INDEX(Matriz!$B$21:$R$21,1,MATCH($U9,Matriz!$B$3:$R$3,0)) -> 0 | AN9: =INDEX(Matriz!$B$22:$R$22,1,MATCH($U9,Matriz!$B$3:$R$3,0)) -> 0 | AO9: =INDEX(Matriz!$B$23:$R$23,1,MATCH($U9,Matriz!$B$3:$R$3,0)) -> 0
A10: 04 — Demanda por Moeda | B10: =INDEX(Matriz!$B$7:$R$7,1,MATCH(VALUE($B$3),Matriz!$B$3:$R$3,0)) -> 2.5 | C10: =B10/SUM($B$7:$B$23) -> 0.05 | U10: 2014 | V10: =IF($B$32="Sim",INDEX(Matriz!$B$4:$R$4,1,MATCH($U10,Matriz!$B$3:$R$3,0)),NA()) -> #N/A | W10: =IF($B$33="Sim",INDEX(Matriz!$B$5:$R$5,1,MATCH($U10,Matriz!$B$3:$R$3,0)),NA()) -> #N/A | X10: =IF($B$34="Sim",INDEX(Matriz!$B$6:$R$6,1,MATCH($U10,Matriz!$B$3:$R$3,0)),NA()) -> #N/A | Y10: =IF($B$35="Sim",INDEX(Matriz!$B$7:$R$7,1,MATCH($U10,Matriz!$B$3:$R$3,0)),NA()) -> #N/A | Z10: =IF($B$36="Sim",INDEX(Matriz!$B$8:$R$8,1,MATCH($U10,Matriz!$B$3:$R$3,0)),NA()) -> #N/A | AA10: =IF($B$37="Sim",INDEX(Matriz!$B$9:$R$9,1,MATCH($U10,Matriz!$B$3:$R$3,0)),NA()) -> 6 | AB10: =IF($B$38="Sim",INDEX(Matriz!$B$10:$R$10,1,MATCH($U10,Matriz!$B$3:$R$3,0)),NA()) -> #N/A | AC10: =IF($B$39="Sim",INDEX(Matriz!$B$11:$R$11,1,MATCH($U10,Matriz!$B$3:$R$3,0)),NA()) -> #N/A | AD10: =IF($B$40="Sim",INDEX(Matriz!$B$12:$R$12,1,MATCH($U10,Matriz!$B$3:$R$3,0)),NA()) -> #N/A | AE10: =IF($B$41="Sim",INDEX(Matriz!$B$13:$R$13,1,MATCH($U10,Matriz!$B$3:$R$3,0)),NA()) -> #N/A | AF10: =IF($B$42="Sim",INDEX(Matriz!$B$14:$R$14,1,MATCH($U10,Matriz!$B$3:$R$3,0)),NA()) -> #N/A | AG10: =IF($B$43="Sim",INDEX(Matriz!$B$15:$R$15,1,MATCH($U10,Matriz!$B$3:$R$3,0)),NA()) -> #N/A | AH10: =IF($B$44="Sim",INDEX(Matriz!$B$16:$R$16,1,MATCH($U10,Matriz!$B$3:$R$3,0)),NA()) -> #N/A | AI10: =IF($B$45="Sim",INDEX(Matriz!$B$17:$R$17,1,MATCH($U10,Matriz!$B$3:$R$3,0)),NA()) -> #N/A | AJ10: =IF($B$46="Sim",INDEX(Matriz!$B$18:$R$18,1,MATCH($U10,Matriz!$B$3:$R$3,0)),NA()) -> #N/A | AK10: =IF($B$47="Sim",INDEX(Matriz!$B$19:$R$19,1,MATCH($U10,Matriz!$B$3:$R$3,0)),NA()) -> #N/A | AL10: =IF($B$48="Sim",INDEX(Matriz!$B$20:$R$20,1,MATCH($U10,Matriz!$B$3:$R$3,0)),NA()) -> #N/A | AM10: =INDEX(Matriz!$B$21:$R$21,1,MATCH($U10,Matriz!$B$3:$R$3,0)) -> 0 | AN10: =INDEX(Matriz!$B$22:$R$22,1,MATCH($U10,Matriz!$B$3:$R$3,0)) -> 0 | AO10: =INDEX(Matriz!$B$23:$R$23,1,MATCH($U10,Matriz!$B$3:$R$3,0)) -> 0
A11: 05 — IS-LM | B11: =INDEX(Matriz!$B$8:$R$8,1,MATCH(VALUE($B$3),Matriz!$B$3:$R$3,0)) -> 2.5 | C11: =B11/SUM($B$7:$B$23) -> 0.05 | U11: 2015 | V11: =IF($B$32="Sim",INDEX(Matriz!$B$4:$R$4,1,MATCH($U11,Matriz!$B$3:$R$3,0)),NA()) -> #N/A | W11: =IF($B$33="Sim",INDEX(Matriz!$B$5:$R$5,1,MATCH($U11,Matriz!$B$3:$R$3,0)),NA()) -> #N/A | X11: =IF($B$34="Sim",INDEX(Matriz!$B$6:$R$6,1,MATCH($U11,Matriz!$B$3:$R$3,0)),NA()) -> #N/A | Y11: =IF($B$35="Sim",INDEX(Matriz!$B$7:$R$7,1,MATCH($U11,Matriz!$B$3:$R$3,0)),NA()) -> #N/A | Z11: =IF($B$36="Sim",INDEX(Matriz!$B$8:$R$8,1,MATCH($U11,Matriz!$B$3:$R$3,0)),NA()) -> #N/A | AA11: =IF($B$37="Sim",INDEX(Matriz!$B$9:$R$9,1,MATCH($U11,Matriz!$B$3:$R$3,0)),NA()) -> 5 | AB11: =IF($B$38="Sim",INDEX(Matriz!$B$10:$R$10,1,MATCH($U11,Matriz!$B$3:$R$3,0)),NA()) -> #N/A | AC11: =IF($B$39="Sim",INDEX(Matriz!$B$11:$R$11,1,MATCH($U11,Matriz!$B$3:$R$3,0)),NA()) -> #N/A | AD11: =IF($B$40="Sim",INDEX(Matriz!$B$12:$R$12,1,MATCH($U11,Matriz!$B$3:$R$3,0)),NA()) -> #N/A | AE11: =IF($B$41="Sim",INDEX(Matriz!$B$13:$R$13,1,MATCH($U11,Matriz!$B$3:$R$3,0)),NA()) -> #N/A | AF11: =IF($B$42="Sim",INDEX(Matriz!$B$14:$R$14,1,MATCH($U11,Matriz!$B$3:$R$3,0)),NA()) -> #N/A | AG11: =IF($B$43="Sim",INDEX(Matriz!$B$15:$R$15,1,MATCH($U11,Matriz!$B$3:$R$3,0)),NA()) -> #N/A | AH11: =IF($B$44="Sim",INDEX(Matriz!$B$16:$R$16,1,MATCH($U11,Matriz!$B$3:$R$3,0)),NA()) -> #N/A | AI11: =IF($B$45="Sim",INDEX(Matriz!$B$17:$R$17,1,MATCH($U11,Matriz!$B$3:$R$3,0)),NA()) -> #N/A | AJ11: =IF($B$46="Sim",INDEX(Matriz!$B$18:$R$18,1,MATCH($U11,Matriz!$B$3:$R$3,0)),NA()) -> #N/A | AK11: =IF($B$47="Sim",INDEX(Matriz!$B$19:$R$19,1,MATCH($U11,Matriz!$B$3:$R$3,0)),NA()) -> #N/A | AL11: =IF($B$48="Sim",INDEX(Matriz!$B$20:$R$20,1,MATCH($U11,Matriz!$B$3:$R$3,0)),NA()) -> #N/A | AM11: =INDEX(Matriz!$B$21:$R$21,1,MATCH($U11,Matriz!$B$3:$R$3,0)) -> 0 | AN11: =INDEX(Matriz!$B$22:$R$22,1,MATCH($U11,Matriz!$B$3:$R$3,0)) -> 0 | AO11: =INDEX(Matriz!$B$23:$R$23,1,MATCH($U11,Matriz!$B$3:$R$3,0)) -> 0
A12: 06 — IS-LM-BP | B12: =INDEX(Matriz!$B$9:$R$9,1,MATCH(VALUE($B$3),Matriz!$B$3:$R$3,0)) -> 0 | C12: =B12/SUM($B$7:$B$23) -> 0 | U12: 2016 | V12: =IF($B$32="Sim",INDEX(Matriz!$B$4:$R$4,1,MATCH($U12,Matriz!$B$3:$R$3,0)),NA()) -> #N/A | W12: =IF($B$33="Sim",INDEX(Matriz!$B$5:$R$5,1,MATCH($U12,Matriz!$B$3:$R$3,0)),NA()) -> #N/A | X12: =IF($B$34="Sim",INDEX(Matriz!$B$6:$R$6,1,MATCH($U12,Matriz!$B$3:$R$3,0)),NA()) -> #N/A | Y12: =IF($B$35="Sim",INDEX(Matriz!$B$7:$R$7,1,MATCH($U12,Matriz!$B$3:$R$3,0)),NA()) -> #N/A | Z12: =IF($B$36="Sim",INDEX(Matriz!$B$8:$R$8,1,MATCH($U12,Matriz!$B$3:$R$3,0)),NA()) -> #N/A | AA12: =IF($B$37="Sim",INDEX(Matriz!$B$9:$R$9,1,MATCH($U12,Matriz!$B$3:$R$3,0)),NA()) -> 4.5 | AB12: =IF($B$38="Sim",INDEX(Matriz!$B$10:$R$10,1,MATCH($U12,Matriz!$B$3:$R$3,0)),NA()) -> #N/A | AC12: =IF($B$39="Sim",INDEX(Matriz!$B$11:$R$11,1,MATCH($U12,Matriz!$B$3:$R$3,0)),NA()) -> #N/A | AD12: =IF($B$40="Sim",INDEX(Matriz!$B$12:$R$12,1,MATCH($U12,Matriz!$B$3:$R$3,0)),NA()) -> #N/A | AE12: =IF($B$41="Sim",INDEX(Matriz!$B$13:$R$13,1,MATCH($U12,Matriz!$B$3:$R$3,0)),NA()) -> #N/A | AF12: =IF($B$42="Sim",INDEX(Matriz!$B$14:$R$14,1,MATCH($U12,Matriz!$B$3:$R$3,0)),NA()) -> #N/A | AG12: =IF($B$43="Sim",INDEX(Matriz!$B$15:$R$15,1,MATCH($U12,Matriz!$B$3:$R$3,0)),NA()) -> #N/A | AH12: =IF($B$44="Sim",INDEX(Matriz!$B$16:$R$16,1,MATCH($U12,Matriz!$B$3:$R$3,0)),NA()) -> #N/A | AI12: =IF($B$45="Sim",INDEX(Matriz!$B$17:$R$17,1,MATCH($U12,Matriz!$B$3:$R$3,0)),NA()) -> #N/A | AJ12: =IF($B$46="Sim",INDEX(Matriz!$B$18:$R$18,1,MATCH($U12,Matriz!$B$3:$R$3,0)),NA()) -> #N/A | AK12: =IF($B$47="Sim",INDEX(Matriz!$B$19:$R$19,1,MATCH($U12,Matriz!$B$3:$R$3,0)),NA()) -> #N/A | AL12: =IF($B$48="Sim",INDEX(Matriz!$B$20:$R$20,1,MATCH($U12,Matriz!$B$3:$R$3,0)),NA()) -> #N/A | AM12: =INDEX(Matriz!$B$21:$R$21,1,MATCH($U12,Matriz!$B$3:$R$3,0)) -> 0 | AN12: =INDEX(Matriz!$B$22:$R$22,1,MATCH($U12,Matriz!$B$3:$R$3,0)) -> 0 | AO12: =INDEX(Matriz!$B$23:$R$23,1,MATCH($U12,Matriz!$B$3:$R$3,0)) -> 0
A13: 07a — Paridades | B13: =INDEX(Matriz!$B$10:$R$10,1,MATCH(VALUE($B$3),Matriz!$B$3:$R$3,0)) -> 5 | C13: =B13/SUM($B$7:$B$23) -> 0.1 | U13: 2017 | V13: =IF($B$32="Sim",INDEX(Matriz!$B$4:$R$4,1,MATCH($U13,Matriz!$B$3:$R$3,0)),NA()) -> #N/A | W13: =IF($B$33="Sim",INDEX(Matriz!$B$5:$R$5,1,MATCH($U13,Matriz!$B$3:$R$3,0)),NA()) -> #N/A | X13: =IF($B$34="Sim",INDEX(Matriz!$B$6:$R$6,1,MATCH($U13,Matriz!$B$3:$R$3,0)),NA()) -> #N/A | Y13: =IF($B$35="Sim",INDEX(Matriz!$B$7:$R$7,1,MATCH($U13,Matriz!$B$3:$R$3,0)),NA()) -> #N/A | Z13: =IF($B$36="Sim",INDEX(Matriz!$B$8:$R$8,1,MATCH($U13,Matriz!$B$3:$R$3,0)),NA()) -> #N/A | AA13: =IF($B$37="Sim",INDEX(Matriz!$B$9:$R$9,1,MATCH($U13,Matriz!$B$3:$R$3,0)),NA()) -> 10 | AB13: =IF($B$38="Sim",INDEX(Matriz!$B$10:$R$10,1,MATCH($U13,Matriz!$B$3:$R$3,0)),NA()) -> #N/A | AC13: =IF($B$39="Sim",INDEX(Matriz!$B$11:$R$11,1,MATCH($U13,Matriz!$B$3:$R$3,0)),NA()) -> #N/A | AD13: =IF($B$40="Sim",INDEX(Matriz!$B$12:$R$12,1,MATCH($U13,Matriz!$B$3:$R$3,0)),NA()) -> #N/A | AE13: =IF($B$41="Sim",INDEX(Matriz!$B$13:$R$13,1,MATCH($U13,Matriz!$B$3:$R$3,0)),NA()) -> #N/A | AF13: =IF($B$42="Sim",INDEX(Matriz!$B$14:$R$14,1,MATCH($U13,Matriz!$B$3:$R$3,0)),NA()) -> #N/A | AG13: =IF($B$43="Sim",INDEX(Matriz!$B$15:$R$15,1,MATCH($U13,Matriz!$B$3:$R$3,0)),NA()) -> #N/A | AH13: =IF($B$44="Sim",INDEX(Matriz!$B$16:$R$16,1,MATCH($U13,Matriz!$B$3:$R$3,0)),NA()) -> #N/A | AI13: =IF($B$45="Sim",INDEX(Matriz!$B$17:$R$17,1,MATCH($U13,Matriz!$B$3:$R$3,0)),NA()) -> #N/A | AJ13: =IF($B$46="Sim",INDEX(Matriz!$B$18:$R$18,1,MATCH($U13,Matriz!$B$3:$R$3,0)),NA()) -> #N/A | AK13: =IF($B$47="Sim",INDEX(Matriz!$B$19:$R$19,1,MATCH($U13,Matriz!$B$3:$R$3,0)),NA()) -> #N/A | AL13: =IF($B$48="Sim",INDEX(Matriz!$B$20:$R$20,1,MATCH($U13,Matriz!$B$3:$R$3,0)),NA()) -> #N/A | AM13: =INDEX(Matriz!$B$21:$R$21,1,MATCH($U13,Matriz!$B$3:$R$3,0)) -> 0 | AN13: =INDEX(Matriz!$B$22:$R$22,1,MATCH($U13,Matriz!$B$3:$R$3,0)) -> 0 | AO13: =INDEX(Matriz!$B$23:$R$23,1,MATCH($U13,Matriz!$B$3:$R$3,0)) -> 0
A14: 07b — OA-DA | B14: =INDEX(Matriz!$B$11:$R$11,1,MATCH(VALUE($B$3),Matriz!$B$3:$R$3,0)) -> 2 | C14: =B14/SUM($B$7:$B$23) -> 0.04 | U14: 2018 | V14: =IF($B$32="Sim",INDEX(Matriz!$B$4:$R$4,1,MATCH($U14,Matriz!$B$3:$R$3,0)),NA()) -> #N/A | W14: =IF($B$33="Sim",INDEX(Matriz!$B$5:$R$5,1,MATCH($U14,Matriz!$B$3:$R$3,0)),NA()) -> #N/A | X14: =IF($B$34="Sim",INDEX(Matriz!$B$6:$R$6,1,MATCH($U14,Matriz!$B$3:$R$3,0)),NA()) -> #N/A | Y14: =IF($B$35="Sim",INDEX(Matriz!$B$7:$R$7,1,MATCH($U14,Matriz!$B$3:$R$3,0)),NA()) -> #N/A | Z14: =IF($B$36="Sim",INDEX(Matriz!$B$8:$R$8,1,MATCH($U14,Matriz!$B$3:$R$3,0)),NA()) -> #N/A | AA14: =IF($B$37="Sim",INDEX(Matriz!$B$9:$R$9,1,MATCH($U14,Matriz!$B$3:$R$3,0)),NA()) -> 10 | AB14: =IF($B$38="Sim",INDEX(Matriz!$B$10:$R$10,1,MATCH($U14,Matriz!$B$3:$R$3,0)),NA()) -> #N/A | AC14: =IF($B$39="Sim",INDEX(Matriz!$B$11:$R$11,1,MATCH($U14,Matriz!$B$3:$R$3,0)),NA()) -> #N/A | AD14: =IF($B$40="Sim",INDEX(Matriz!$B$12:$R$12,1,MATCH($U14,Matriz!$B$3:$R$3,0)),NA()) -> #N/A | AE14: =IF($B$41="Sim",INDEX(Matriz!$B$13:$R$13,1,MATCH($U14,Matriz!$B$3:$R$3,0)),NA()) -> #N/A | AF14: =IF($B$42="Sim",INDEX(Matriz!$B$14:$R$14,1,MATCH($U14,Matriz!$B$3:$R$3,0)),NA()) -> #N/A | AG14: =IF($B$43="Sim",INDEX(Matriz!$B$15:$R$15,1,MATCH($U14,Matriz!$B$3:$R$3,0)),NA()) -> #N/A | AH14: =IF($B$44="Sim",INDEX(Matriz!$B$16:$R$16,1,MATCH($U14,Matriz!$B$3:$R$3,0)),NA()) -> #N/A | AI14: =IF($B$45="Sim",INDEX(Matriz!$B$17:$R$17,1,MATCH($U14,Matriz!$B$3:$R$3,0)),NA()) -> #N/A | AJ14: =IF($B$46="Sim",INDEX(Matriz!$B$18:$R$18,1,MATCH($U14,Matriz!$B$3:$R$3,0)),NA()) -> #N/A | AK14: =IF($B$47="Sim",INDEX(Matriz!$B$19:$R$19,1,MATCH($U14,Matriz!$B$3:$R$3,0)),NA()) -> #N/A | AL14: =IF($B$48="Sim",INDEX(Matriz!$B$20:$R$20,1,MATCH($U14,Matriz!$B$3:$R$3,0)),NA()) -> #N/A | AM14: =INDEX(Matriz!$B$21:$R$21,1,MATCH($U14,Matriz!$B$3:$R$3,0)) -> 0 | AN14: =INDEX(Matriz!$B$22:$R$22,1,MATCH($U14,Matriz!$B$3:$R$3,0)) -> 0 | AO14: =INDEX(Matriz!$B$23:$R$23,1,MATCH($U14,Matriz!$B$3:$R$3,0)) -> 0
A15: 08 — Curva de Phillips | B15: =INDEX(Matriz!$B$12:$R$12,1,MATCH(VALUE($B$3),Matriz!$B$3:$R$3,0)) -> 1.5 | C15: =B15/SUM($B$7:$B$23) -> 0.03 | U15: 2019 | V15: =IF($B$32="Sim",INDEX(Matriz!$B$4:$R$4,1,MATCH($U15,Matriz!$B$3:$R$3,0)),NA()) -> #N/A | W15: =IF($B$33="Sim",INDEX(Matriz!$B$5:$R$5,1,MATCH($U15,Matriz!$B$3:$R$3,0)),NA()) -> #N/A | X15: =IF($B$34="Sim",INDEX(Matriz!$B$6:$R$6,1,MATCH($U15,Matriz!$B$3:$R$3,0)),NA()) -> #N/A | Y15: =IF($B$35="Sim",INDEX(Matriz!$B$7:$R$7,1,MATCH($U15,Matriz!$B$3:$R$3,0)),NA()) -> #N/A | Z15: =IF($B$36="Sim",INDEX(Matriz!$B$8:$R$8,1,MATCH($U15,Matriz!$B$3:$R$3,0)),NA()) -> #N/A | AA15: =IF($B$37="Sim",INDEX(Matriz!$B$9:$R$9,1,MATCH($U15,Matriz!$B$3:$R$3,0)),NA()) -> 10 | AB15: =IF($B$38="Sim",INDEX(Matriz!$B$10:$R$10,1,MATCH($U15,Matriz!$B$3:$R$3,0)),NA()) -> #N/A | AC15: =IF($B$39="Sim",INDEX(Matriz!$B$11:$R$11,1,MATCH($U15,Matriz!$B$3:$R$3,0)),NA()) -> #N/A | AD15: =IF($B$40="Sim",INDEX(Matriz!$B$12:$R$12,1,MATCH($U15,Matriz!$B$3:$R$3,0)),NA()) -> #N/A | AE15: =IF($B$41="Sim",INDEX(Matriz!$B$13:$R$13,1,MATCH($U15,Matriz!$B$3:$R$3,0)),NA()) -> #N/A | AF15: =IF($B$42="Sim",INDEX(Matriz!$B$14:$R$14,1,MATCH($U15,Matriz!$B$3:$R$3,0)),NA()) -> #N/A | AG15: =IF($B$43="Sim",INDEX(Matriz!$B$15:$R$15,1,MATCH($U15,Matriz!$B$3:$R$3,0)),NA()) -> #N/A | AH15: =IF($B$44="Sim",INDEX(Matriz!$B$16:$R$16,1,MATCH($U15,Matriz!$B$3:$R$3,0)),NA()) -> #N/A | AI15: =IF($B$45="Sim",INDEX(Matriz!$B$17:$R$17,1,MATCH($U15,Matriz!$B$3:$R$3,0)),NA()) -> #N/A | AJ15: =IF($B$46="Sim",INDEX(Matriz!$B$18:$R$18,1,MATCH($U15,Matriz!$B$3:$R$3,0)),NA()) -> #N/A | AK15: =IF($B$47="Sim",INDEX(Matriz!$B$19:$R$19,1,MATCH($U15,Matriz!$B$3:$R$3,0)),NA()) -> #N/A | AL15: =IF($B$48="Sim",INDEX(Matriz!$B$20:$R$20,1,MATCH($U15,Matriz!$B$3:$R$3,0)),NA()) -> #N/A | AM15: =INDEX(Matriz!$B$21:$R$21,1,MATCH($U15,Matriz!$B$3:$R$3,0)) -> 0 | AN15: =INDEX(Matriz!$B$22:$R$22,1,MATCH($U15,Matriz!$B$3:$R$3,0)) -> 0 | AO15: =INDEX(Matriz!$B$23:$R$23,1,MATCH($U15,Matriz!$B$3:$R$3,0)) -> 0
A16: 09 — Expectativas, Novos Clássicos e Novos Keynesianos | B16: =INDEX(Matriz!$B$13:$R$13,1,MATCH(VALUE($B$3),Matriz!$B$3:$R$3,0)) -> 12 | C16: =B16/SUM($B$7:$B$23) -> 0.24 | U16: 2020 | V16: =IF($B$32="Sim",INDEX(Matriz!$B$4:$R$4,1,MATCH($U16,Matriz!$B$3:$R$3,0)),NA()) -> #N/A | W16: =IF($B$33="Sim",INDEX(Matriz!$B$5:$R$5,1,MATCH($U16,Matriz!$B$3:$R$3,0)),NA()) -> #N/A | X16: =IF($B$34="Sim",INDEX(Matriz!$B$6:$R$6,1,MATCH($U16,Matriz!$B$3:$R$3,0)),NA()) -> #N/A | Y16: =IF($B$35="Sim",INDEX(Matriz!$B$7:$R$7,1,MATCH($U16,Matriz!$B$3:$R$3,0)),NA()) -> #N/A | Z16: =IF($B$36="Sim",INDEX(Matriz!$B$8:$R$8,1,MATCH($U16,Matriz!$B$3:$R$3,0)),NA()) -> #N/A | AA16: =IF($B$37="Sim",INDEX(Matriz!$B$9:$R$9,1,MATCH($U16,Matriz!$B$3:$R$3,0)),NA()) -> 5 | AB16: =IF($B$38="Sim",INDEX(Matriz!$B$10:$R$10,1,MATCH($U16,Matriz!$B$3:$R$3,0)),NA()) -> #N/A | AC16: =IF($B$39="Sim",INDEX(Matriz!$B$11:$R$11,1,MATCH($U16,Matriz!$B$3:$R$3,0)),NA()) -> #N/A | AD16: =IF($B$40="Sim",INDEX(Matriz!$B$12:$R$12,1,MATCH($U16,Matriz!$B$3:$R$3,0)),NA()) -> #N/A | AE16: =IF($B$41="Sim",INDEX(Matriz!$B$13:$R$13,1,MATCH($U16,Matriz!$B$3:$R$3,0)),NA()) -> #N/A | AF16: =IF($B$42="Sim",INDEX(Matriz!$B$14:$R$14,1,MATCH($U16,Matriz!$B$3:$R$3,0)),NA()) -> #N/A | AG16: =IF($B$43="Sim",INDEX(Matriz!$B$15:$R$15,1,MATCH($U16,Matriz!$B$3:$R$3,0)),NA()) -> #N/A | AH16: =IF($B$44="Sim",INDEX(Matriz!$B$16:$R$16,1,MATCH($U16,Matriz!$B$3:$R$3,0)),NA()) -> #N/A | AI16: =IF($B$45="Sim",INDEX(Matriz!$B$17:$R$17,1,MATCH($U16,Matriz!$B$3:$R$3,0)),NA()) -> #N/A | AJ16: =IF($B$46="Sim",INDEX(Matriz!$B$18:$R$18,1,MATCH($U16,Matriz!$B$3:$R$3,0)),NA()) -> #N/A | AK16: =IF($B$47="Sim",INDEX(Matriz!$B$19:$R$19,1,MATCH($U16,Matriz!$B$3:$R$3,0)),NA()) -> #N/A | AL16: =IF($B$48="Sim",INDEX(Matriz!$B$20:$R$20,1,MATCH($U16,Matriz!$B$3:$R$3,0)),NA()) -> #N/A | AM16: =INDEX(Matriz!$B$21:$R$21,1,MATCH($U16,Matriz!$B$3:$R$3,0)) -> 0 | AN16: =INDEX(Matriz!$B$22:$R$22,1,MATCH($U16,Matriz!$B$3:$R$3,0)) -> 0 | AO16: =INDEX(Matriz!$B$23:$R$23,1,MATCH($U16,Matriz!$B$3:$R$3,0)) -> 0
A17: 10 — Ciclos Reais de Negócios (RBC) | B17: =INDEX(Matriz!$B$14:$R$14,1,MATCH(VALUE($B$3),Matriz!$B$3:$R$3,0)) -> 1 | C17: =B17/SUM($B$7:$B$23) -> 0.02 | U17: 2021 | V17: =IF($B$32="Sim",INDEX(Matriz!$B$4:$R$4,1,MATCH($U17,Matriz!$B$3:$R$3,0)),NA()) -> #N/A | W17: =IF($B$33="Sim",INDEX(Matriz!$B$5:$R$5,1,MATCH($U17,Matriz!$B$3:$R$3,0)),NA()) -> #N/A | X17: =IF($B$34="Sim",INDEX(Matriz!$B$6:$R$6,1,MATCH($U17,Matriz!$B$3:$R$3,0)),NA()) -> #N/A | Y17: =IF($B$35="Sim",INDEX(Matriz!$B$7:$R$7,1,MATCH($U17,Matriz!$B$3:$R$3,0)),NA()) -> #N/A | Z17: =IF($B$36="Sim",INDEX(Matriz!$B$8:$R$8,1,MATCH($U17,Matriz!$B$3:$R$3,0)),NA()) -> #N/A | AA17: =IF($B$37="Sim",INDEX(Matriz!$B$9:$R$9,1,MATCH($U17,Matriz!$B$3:$R$3,0)),NA()) -> 10 | AB17: =IF($B$38="Sim",INDEX(Matriz!$B$10:$R$10,1,MATCH($U17,Matriz!$B$3:$R$3,0)),NA()) -> #N/A | AC17: =IF($B$39="Sim",INDEX(Matriz!$B$11:$R$11,1,MATCH($U17,Matriz!$B$3:$R$3,0)),NA()) -> #N/A | AD17: =IF($B$40="Sim",INDEX(Matriz!$B$12:$R$12,1,MATCH($U17,Matriz!$B$3:$R$3,0)),NA()) -> #N/A | AE17: =IF($B$41="Sim",INDEX(Matriz!$B$13:$R$13,1,MATCH($U17,Matriz!$B$3:$R$3,0)),NA()) -> #N/A | AF17: =IF($B$42="Sim",INDEX(Matriz!$B$14:$R$14,1,MATCH($U17,Matriz!$B$3:$R$3,0)),NA()) -> #N/A | AG17: =IF($B$43="Sim",INDEX(Matriz!$B$15:$R$15,1,MATCH($U17,Matriz!$B$3:$R$3,0)),NA()) -> #N/A | AH17: =IF($B$44="Sim",INDEX(Matriz!$B$16:$R$16,1,MATCH($U17,Matriz!$B$3:$R$3,0)),NA()) -> #N/A | AI17: =IF($B$45="Sim",INDEX(Matriz!$B$17:$R$17,1,MATCH($U17,Matriz!$B$3:$R$3,0)),NA()) -> #N/A | AJ17: =IF($B$46="Sim",INDEX(Matriz!$B$18:$R$18,1,MATCH($U17,Matriz!$B$3:$R$3,0)),NA()) -> #N/A | AK17: =IF($B$47="Sim",INDEX(Matriz!$B$19:$R$19,1,MATCH($U17,Matriz!$B$3:$R$3,0)),NA()) -> #N/A | AL17: =IF($B$48="Sim",INDEX(Matriz!$B$20:$R$20,1,MATCH($U17,Matriz!$B$3:$R$3,0)),NA()) -> #N/A | AM17: =INDEX(Matriz!$B$21:$R$21,1,MATCH($U17,Matriz!$B$3:$R$3,0)) -> 0 | AN17: =INDEX(Matriz!$B$22:$R$22,1,MATCH($U17,Matriz!$B$3:$R$3,0)) -> 0 | AO17: =INDEX(Matriz!$B$23:$R$23,1,MATCH($U17,Matriz!$B$3:$R$3,0)) -> 0
A18: 11 — Crescimento Econômico | B18: =INDEX(Matriz!$B$15:$R$15,1,MATCH(VALUE($B$3),Matriz!$B$3:$R$3,0)) -> 5 | C18: =B18/SUM($B$7:$B$23) -> 0.1 | U18: 2022 | V18: =IF($B$32="Sim",INDEX(Matriz!$B$4:$R$4,1,MATCH($U18,Matriz!$B$3:$R$3,0)),NA()) -> #N/A | W18: =IF($B$33="Sim",INDEX(Matriz!$B$5:$R$5,1,MATCH($U18,Matriz!$B$3:$R$3,0)),NA()) -> #N/A | X18: =IF($B$34="Sim",INDEX(Matriz!$B$6:$R$6,1,MATCH($U18,Matriz!$B$3:$R$3,0)),NA()) -> #N/A | Y18: =IF($B$35="Sim",INDEX(Matriz!$B$7:$R$7,1,MATCH($U18,Matriz!$B$3:$R$3,0)),NA()) -> #N/A | Z18: =IF($B$36="Sim",INDEX(Matriz!$B$8:$R$8,1,MATCH($U18,Matriz!$B$3:$R$3,0)),NA()) -> #N/A | AA18: =IF($B$37="Sim",INDEX(Matriz!$B$9:$R$9,1,MATCH($U18,Matriz!$B$3:$R$3,0)),NA()) -> 8 | AB18: =IF($B$38="Sim",INDEX(Matriz!$B$10:$R$10,1,MATCH($U18,Matriz!$B$3:$R$3,0)),NA()) -> #N/A | AC18: =IF($B$39="Sim",INDEX(Matriz!$B$11:$R$11,1,MATCH($U18,Matriz!$B$3:$R$3,0)),NA()) -> #N/A | AD18: =IF($B$40="Sim",INDEX(Matriz!$B$12:$R$12,1,MATCH($U18,Matriz!$B$3:$R$3,0)),NA()) -> #N/A | AE18: =IF($B$41="Sim",INDEX(Matriz!$B$13:$R$13,1,MATCH($U18,Matriz!$B$3:$R$3,0)),NA()) -> #N/A | AF18: =IF($B$42="Sim",INDEX(Matriz!$B$14:$R$14,1,MATCH($U18,Matriz!$B$3:$R$3,0)),NA()) -> #N/A | AG18: =IF($B$43="Sim",INDEX(Matriz!$B$15:$R$15,1,MATCH($U18,Matriz!$B$3:$R$3,0)),NA()) -> #N/A | AH18: =IF($B$44="Sim",INDEX(Matriz!$B$16:$R$16,1,MATCH($U18,Matriz!$B$3:$R$3,0)),NA()) -> #N/A | AI18: =IF($B$45="Sim",INDEX(Matriz!$B$17:$R$17,1,MATCH($U18,Matriz!$B$3:$R$3,0)),NA()) -> #N/A | AJ18: =IF($B$46="Sim",INDEX(Matriz!$B$18:$R$18,1,MATCH($U18,Matriz!$B$3:$R$3,0)),NA()) -> #N/A | AK18: =IF($B$47="Sim",INDEX(Matriz!$B$19:$R$19,1,MATCH($U18,Matriz!$B$3:$R$3,0)),NA()) -> #N/A | AL18: =IF($B$48="Sim",INDEX(Matriz!$B$20:$R$20,1,MATCH($U18,Matriz!$B$3:$R$3,0)),NA()) -> #N/A | AM18: =INDEX(Matriz!$B$21:$R$21,1,MATCH($U18,Matriz!$B$3:$R$3,0)) -> 0 | AN18: =INDEX(Matriz!$B$22:$R$22,1,MATCH($U18,Matriz!$B$3:$R$3,0)) -> 0 | AO18: =INDEX(Matriz!$B$23:$R$23,1,MATCH($U18,Matriz!$B$3:$R$3,0)) -> 0
A19: 12 — Consumo | B19: =INDEX(Matriz!$B$16:$R$16,1,MATCH(VALUE($B$3),Matriz!$B$3:$R$3,0)) -> 2 | C19: =B19/SUM($B$7:$B$23) -> 0.04 | U19: 2023 | V19: =IF($B$32="Sim",INDEX(Matriz!$B$4:$R$4,1,MATCH($U19,Matriz!$B$3:$R$3,0)),NA()) -> #N/A | W19: =IF($B$33="Sim",INDEX(Matriz!$B$5:$R$5,1,MATCH($U19,Matriz!$B$3:$R$3,0)),NA()) -> #N/A | X19: =IF($B$34="Sim",INDEX(Matriz!$B$6:$R$6,1,MATCH($U19,Matriz!$B$3:$R$3,0)),NA()) -> #N/A | Y19: =IF($B$35="Sim",INDEX(Matriz!$B$7:$R$7,1,MATCH($U19,Matriz!$B$3:$R$3,0)),NA()) -> #N/A | Z19: =IF($B$36="Sim",INDEX(Matriz!$B$8:$R$8,1,MATCH($U19,Matriz!$B$3:$R$3,0)),NA()) -> #N/A | AA19: =IF($B$37="Sim",INDEX(Matriz!$B$9:$R$9,1,MATCH($U19,Matriz!$B$3:$R$3,0)),NA()) -> 11 | AB19: =IF($B$38="Sim",INDEX(Matriz!$B$10:$R$10,1,MATCH($U19,Matriz!$B$3:$R$3,0)),NA()) -> #N/A | AC19: =IF($B$39="Sim",INDEX(Matriz!$B$11:$R$11,1,MATCH($U19,Matriz!$B$3:$R$3,0)),NA()) -> #N/A | AD19: =IF($B$40="Sim",INDEX(Matriz!$B$12:$R$12,1,MATCH($U19,Matriz!$B$3:$R$3,0)),NA()) -> #N/A | AE19: =IF($B$41="Sim",INDEX(Matriz!$B$13:$R$13,1,MATCH($U19,Matriz!$B$3:$R$3,0)),NA()) -> #N/A | AF19: =IF($B$42="Sim",INDEX(Matriz!$B$14:$R$14,1,MATCH($U19,Matriz!$B$3:$R$3,0)),NA()) -> #N/A | AG19: =IF($B$43="Sim",INDEX(Matriz!$B$15:$R$15,1,MATCH($U19,Matriz!$B$3:$R$3,0)),NA()) -> #N/A | AH19: =IF($B$44="Sim",INDEX(Matriz!$B$16:$R$16,1,MATCH($U19,Matriz!$B$3:$R$3,0)),NA()) -> #N/A | AI19: =IF($B$45="Sim",INDEX(Matriz!$B$17:$R$17,1,MATCH($U19,Matriz!$B$3:$R$3,0)),NA()) -> #N/A | AJ19: =IF($B$46="Sim",INDEX(Matriz!$B$18:$R$18,1,MATCH($U19,Matriz!$B$3:$R$3,0)),NA()) -> #N/A | AK19: =IF($B$47="Sim",INDEX(Matriz!$B$19:$R$19,1,MATCH($U19,Matriz!$B$3:$R$3,0)),NA()) -> #N/A | AL19: =IF($B$48="Sim",INDEX(Matriz!$B$20:$R$20,1,MATCH($U19,Matriz!$B$3:$R$3,0)),NA()) -> #N/A | AM19: =INDEX(Matriz!$B$21:$R$21,1,MATCH($U19,Matriz!$B$3:$R$3,0)) -> 0 | AN19: =INDEX(Matriz!$B$22:$R$22,1,MATCH($U19,Matriz!$B$3:$R$3,0)) -> 0 | AO19: =INDEX(Matriz!$B$23:$R$23,1,MATCH($U19,Matriz!$B$3:$R$3,0)) -> 0
A20: 13 — Investimento | B20: =INDEX(Matriz!$B$17:$R$17,1,MATCH(VALUE($B$3),Matriz!$B$3:$R$3,0)) -> 2 | C20: =B20/SUM($B$7:$B$23) -> 0.04 | U20: 2024 | V20: =IF($B$32="Sim",INDEX(Matriz!$B$4:$R$4,1,MATCH($U20,Matriz!$B$3:$R$3,0)),NA()) -> #N/A | W20: =IF($B$33="Sim",INDEX(Matriz!$B$5:$R$5,1,MATCH($U20,Matriz!$B$3:$R$3,0)),NA()) -> #N/A | X20: =IF($B$34="Sim",INDEX(Matriz!$B$6:$R$6,1,MATCH($U20,Matriz!$B$3:$R$3,0)),NA()) -> #N/A | Y20: =IF($B$35="Sim",INDEX(Matriz!$B$7:$R$7,1,MATCH($U20,Matriz!$B$3:$R$3,0)),NA()) -> #N/A | Z20: =IF($B$36="Sim",INDEX(Matriz!$B$8:$R$8,1,MATCH($U20,Matriz!$B$3:$R$3,0)),NA()) -> #N/A | AA20: =IF($B$37="Sim",INDEX(Matriz!$B$9:$R$9,1,MATCH($U20,Matriz!$B$3:$R$3,0)),NA()) -> 8 | AB20: =IF($B$38="Sim",INDEX(Matriz!$B$10:$R$10,1,MATCH($U20,Matriz!$B$3:$R$3,0)),NA()) -> #N/A | AC20: =IF($B$39="Sim",INDEX(Matriz!$B$11:$R$11,1,MATCH($U20,Matriz!$B$3:$R$3,0)),NA()) -> #N/A | AD20: =IF($B$40="Sim",INDEX(Matriz!$B$12:$R$12,1,MATCH($U20,Matriz!$B$3:$R$3,0)),NA()) -> #N/A | AE20: =IF($B$41="Sim",INDEX(Matriz!$B$13:$R$13,1,MATCH($U20,Matriz!$B$3:$R$3,0)),NA()) -> #N/A | AF20: =IF($B$42="Sim",INDEX(Matriz!$B$14:$R$14,1,MATCH($U20,Matriz!$B$3:$R$3,0)),NA()) -> #N/A | AG20: =IF($B$43="Sim",INDEX(Matriz!$B$15:$R$15,1,MATCH($U20,Matriz!$B$3:$R$3,0)),NA()) -> #N/A | AH20: =IF($B$44="Sim",INDEX(Matriz!$B$16:$R$16,1,MATCH($U20,Matriz!$B$3:$R$3,0)),NA()) -> #N/A | AI20: =IF($B$45="Sim",INDEX(Matriz!$B$17:$R$17,1,MATCH($U20,Matriz!$B$3:$R$3,0)),NA()) -> #N/A | AJ20: =IF($B$46="Sim",INDEX(Matriz!$B$18:$R$18,1,MATCH($U20,Matriz!$B$3:$R$3,0)),NA()) -> #N/A | AK20: =IF($B$47="Sim",INDEX(Matriz!$B$19:$R$19,1,MATCH($U20,Matriz!$B$3:$R$3,0)),NA()) -> #N/A | AL20: =IF($B$48="Sim",INDEX(Matriz!$B$20:$R$20,1,MATCH($U20,Matriz!$B$3:$R$3,0)),NA()) -> #N/A | AM20: =INDEX(Matriz!$B$21:$R$21,1,MATCH($U20,Matriz!$B$3:$R$3,0)) -> 0 | AN20: =INDEX(Matriz!$B$22:$R$22,1,MATCH($U20,Matriz!$B$3:$R$3,0)) -> 0 | AO20: =INDEX(Matriz!$B$23:$R$23,1,MATCH($U20,Matriz!$B$3:$R$3,0)) -> 0
A21: 14 — Dívida Pública e Senhoriagem | B21: =INDEX(Matriz!$B$18:$R$18,1,MATCH(VALUE($B$3),Matriz!$B$3:$R$3,0)) -> 3 | C21: =B21/SUM($B$7:$B$23) -> 0.06 | U21: 2025 | V21: =IF($B$32="Sim",INDEX(Matriz!$B$4:$R$4,1,MATCH($U21,Matriz!$B$3:$R$3,0)),NA()) -> #N/A | W21: =IF($B$33="Sim",INDEX(Matriz!$B$5:$R$5,1,MATCH($U21,Matriz!$B$3:$R$3,0)),NA()) -> #N/A | X21: =IF($B$34="Sim",INDEX(Matriz!$B$6:$R$6,1,MATCH($U21,Matriz!$B$3:$R$3,0)),NA()) -> #N/A | Y21: =IF($B$35="Sim",INDEX(Matriz!$B$7:$R$7,1,MATCH($U21,Matriz!$B$3:$R$3,0)),NA()) -> #N/A | Z21: =IF($B$36="Sim",INDEX(Matriz!$B$8:$R$8,1,MATCH($U21,Matriz!$B$3:$R$3,0)),NA()) -> #N/A | AA21: =IF($B$37="Sim",INDEX(Matriz!$B$9:$R$9,1,MATCH($U21,Matriz!$B$3:$R$3,0)),NA()) -> 0 | AB21: =IF($B$38="Sim",INDEX(Matriz!$B$10:$R$10,1,MATCH($U21,Matriz!$B$3:$R$3,0)),NA()) -> #N/A | AC21: =IF($B$39="Sim",INDEX(Matriz!$B$11:$R$11,1,MATCH($U21,Matriz!$B$3:$R$3,0)),NA()) -> #N/A | AD21: =IF($B$40="Sim",INDEX(Matriz!$B$12:$R$12,1,MATCH($U21,Matriz!$B$3:$R$3,0)),NA()) -> #N/A | AE21: =IF($B$41="Sim",INDEX(Matriz!$B$13:$R$13,1,MATCH($U21,Matriz!$B$3:$R$3,0)),NA()) -> #N/A | AF21: =IF($B$42="Sim",INDEX(Matriz!$B$14:$R$14,1,MATCH($U21,Matriz!$B$3:$R$3,0)),NA()) -> #N/A | AG21: =IF($B$43="Sim",INDEX(Matriz!$B$15:$R$15,1,MATCH($U21,Matriz!$B$3:$R$3,0)),NA()) -> #N/A | AH21: =IF($B$44="Sim",INDEX(Matriz!$B$16:$R$16,1,MATCH($U21,Matriz!$B$3:$R$3,0)),NA()) -> #N/A | AI21: =IF($B$45="Sim",INDEX(Matriz!$B$17:$R$17,1,MATCH($U21,Matriz!$B$3:$R$3,0)),NA()) -> #N/A | AJ21: =IF($B$46="Sim",INDEX(Matriz!$B$18:$R$18,1,MATCH($U21,Matriz!$B$3:$R$3,0)),NA()) -> #N/A | AK21: =IF($B$47="Sim",INDEX(Matriz!$B$19:$R$19,1,MATCH($U21,Matriz!$B$3:$R$3,0)),NA()) -> #N/A | AL21: =IF($B$48="Sim",INDEX(Matriz!$B$20:$R$20,1,MATCH($U21,Matriz!$B$3:$R$3,0)),NA()) -> #N/A | AM21: =INDEX(Matriz!$B$21:$R$21,1,MATCH($U21,Matriz!$B$3:$R$3,0)) -> 0 | AN21: =INDEX(Matriz!$B$22:$R$22,1,MATCH($U21,Matriz!$B$3:$R$3,0)) -> 0 | AO21: =INDEX(Matriz!$B$23:$R$23,1,MATCH($U21,Matriz!$B$3:$R$3,0)) -> 0
A22: E1 — Mercados Financeiros | B22: =INDEX(Matriz!$B$19:$R$19,1,MATCH(VALUE($B$3),Matriz!$B$3:$R$3,0)) -> 0 | C22: =B22/SUM($B$7:$B$23) -> 0 | U22: 2026 | V22: =IF($B$32="Sim",INDEX(Matriz!$B$4:$R$4,1,MATCH($U22,Matriz!$B$3:$R$3,0)),NA()) -> #N/A | W22: =IF($B$33="Sim",INDEX(Matriz!$B$5:$R$5,1,MATCH($U22,Matriz!$B$3:$R$3,0)),NA()) -> #N/A | X22: =IF($B$34="Sim",INDEX(Matriz!$B$6:$R$6,1,MATCH($U22,Matriz!$B$3:$R$3,0)),NA()) -> #N/A | Y22: =IF($B$35="Sim",INDEX(Matriz!$B$7:$R$7,1,MATCH($U22,Matriz!$B$3:$R$3,0)),NA()) -> #N/A | Z22: =IF($B$36="Sim",INDEX(Matriz!$B$8:$R$8,1,MATCH($U22,Matriz!$B$3:$R$3,0)),NA()) -> #N/A | AA22: =IF($B$37="Sim",INDEX(Matriz!$B$9:$R$9,1,MATCH($U22,Matriz!$B$3:$R$3,0)),NA()) -> 0 | AB22: =IF($B$38="Sim",INDEX(Matriz!$B$10:$R$10,1,MATCH($U22,Matriz!$B$3:$R$3,0)),NA()) -> #N/A | AC22: =IF($B$39="Sim",INDEX(Matriz!$B$11:$R$11,1,MATCH($U22,Matriz!$B$3:$R$3,0)),NA()) -> #N/A | AD22: =IF($B$40="Sim",INDEX(Matriz!$B$12:$R$12,1,MATCH($U22,Matriz!$B$3:$R$3,0)),NA()) -> #N/A | AE22: =IF($B$41="Sim",INDEX(Matriz!$B$13:$R$13,1,MATCH($U22,Matriz!$B$3:$R$3,0)),NA()) -> #N/A | AF22: =IF($B$42="Sim",INDEX(Matriz!$B$14:$R$14,1,MATCH($U22,Matriz!$B$3:$R$3,0)),NA()) -> #N/A | AG22: =IF($B$43="Sim",INDEX(Matriz!$B$15:$R$15,1,MATCH($U22,Matriz!$B$3:$R$3,0)),NA()) -> #N/A | AH22: =IF($B$44="Sim",INDEX(Matriz!$B$16:$R$16,1,MATCH($U22,Matriz!$B$3:$R$3,0)),NA()) -> #N/A | AI22: =IF($B$45="Sim",INDEX(Matriz!$B$17:$R$17,1,MATCH($U22,Matriz!$B$3:$R$3,0)),NA()) -> #N/A | AJ22: =IF($B$46="Sim",INDEX(Matriz!$B$18:$R$18,1,MATCH($U22,Matriz!$B$3:$R$3,0)),NA()) -> #N/A | AK22: =IF($B$47="Sim",INDEX(Matriz!$B$19:$R$19,1,MATCH($U22,Matriz!$B$3:$R$3,0)),NA()) -> #N/A | AL22: =IF($B$48="Sim",INDEX(Matriz!$B$20:$R$20,1,MATCH($U22,Matriz!$B$3:$R$3,0)),NA()) -> #N/A | AM22: =INDEX(Matriz!$B$21:$R$21,1,MATCH($U22,Matriz!$B$3:$R$3,0)) -> 0 | AN22: =INDEX(Matriz!$B$22:$R$22,1,MATCH($U22,Matriz!$B$3:$R$3,0)) -> 0 | AO22: =INDEX(Matriz!$B$23:$R$23,1,MATCH($U22,Matriz!$B$3:$R$3,0)) -> 0
A23: E2 — Demanda de Bens e Complementaridade | B23: =INDEX(Matriz!$B$20:$R$20,1,MATCH(VALUE($B$3),Matriz!$B$3:$R$3,0)) -> 0 | C23: =B23/SUM($B$7:$B$23) -> 0
A30: Filtro de tópicos — série temporal
A31: Tópico | B31: Incluir?
A32: 01 — Contas Nacionais | B32: Não
A33: 02 — Balanço de Pagamentos | B33: Não
A34: 03 — Sistema Monetário | B34: Não
A35: 04 — Demanda por Moeda | B35: Não
A36: 05 — IS-LM | B36: Não
A37: 06 — IS-LM-BP | B37: Sim
A38: 07a — Paridades | B38: Não
A39: 07b — OA-DA | B39: Não
A40: 08 — Curva de Phillips | B40: Não
A41: 09 — Expectativas, Novos Clássicos e Novos Keynesianos | B41: Não
A42: 10 — Ciclos Reais de Negócios (RBC) | B42: Não
... A48: E2 — Demanda de Bens e Complementaridade | B48: Não

Sheet Base_Itens
A1: Base detalhada — classificação item a item
A2: Regra de peso: item V/F = 1; questão aberta/numérica = 5 itens equivalentes. Se um mesmo item pertencer a n tópicos, repita o mesmo Item_ID em n linhas (uma por tópico): cada linha recebe Peso base/n.
A4: Ano | B4: Questão | C4: Item | D4: Tipo | E4: Item_ID | F4: Peso base | G4: Tópico | H4: n tópicos | I4: Pontos do tópico | J4: Observação | K4: Fonte/URL
A5: 2010 | B5: 1 | C5: 0 | D5: V/F | E5: =IF(A5="","",TEXT(A5,"0")&"-Q"&TEXT(B5,"0")&"-"&IF(C5="","ABERTA",C5)) -> 2010-Q1-0 | F5: =IF(D5="V/F",1,IF(D5="Aberta/numérica",5,"")) -> 1 | G5: 01 — Contas Nacionais | H5: =IF(A5="","",IF(C5="",COUNTIFS($A$5:$A$1504,A5,$B$5:$B$1504,B5,$C$5:$C$1504,"",$D$5:$D$1504,D5),COUNTIFS($A$5:$A$1504,A5,$B$5:$B$1504,B5,$C$5:$C$1504,C5,$D$5:$D$1504,D5))) -> 1 | I5: =IF(OR(F5="",H5="",G5=""),"",F5/H5) -> 1 | J5: Identidade do produto e absorção em economia aberta. | K5: Prova Macroeconomia 2010.pdf — p. 5 — Q1 item 0
A6: 2010 | B6: 1 | C6: 1 | D6: V/F | E6: =IF(A6="","",TEXT(A6,"0")&"-Q"&TEXT(B6,"0")&"-"&IF(C6="","ABERTA",C6)) -> 2010-Q1-1 | F6: =IF(D6="V/F",1,IF(D6="Aberta/numérica",5,"")) -> 1 | G6: 01 — Contas Nacionais | H6: =IF(A6="","",IF(C6="",COUNTIFS($A$5:$A$1504,A6,$B$5:$B$1504,B6,$C$5:$C$1504,"",$D$5:$D$1504,D6),COUNTIFS($A$5:$A$1504,A6,$B$5:$B$1504,B6,$C$5:$C$1504,C6,$D$5:$D$1504,D6))) -> 1 | I6: =IF(OR(F6="",H6="",G6=""),"",F6/H6) -> 1 | J6: Identidade poupança-investimento e saldo corrente. | K6: Prova Macroeconomia 2010.pdf — p. 5 — Q1 item 1
A7: 2010 | B7: 1 | C7: 2 | D7: V/F | E7: =IF(A7="","",TEXT(A7,"0")&"-Q"&TEXT(B7,"0")&"-"&IF(C7="","ABERTA",C7)) -> 2010-Q1-2 | F7: =IF(D7="V/F",1,IF(D7="Aberta/numérica",5,"")) -> 1 | G7: 01 — Contas Nacionais | H7: =IF(A7="","",IF(C7="",COUNTIFS($A$5:$A$1504,A7,$B$5:$B$1504,B7,$C$5:$C$1504,"",$D$5:$D$1504,D7),COUNTIFS($A$5:$A$1504,A7,$B$5:$B$1504,B7,$C$5:$C$1504,C7,$D$5:$D$1504,D7))) -> 1 | I7: =IF(OR(F7="",H7="",G7=""),"",F7/H7) -> 1 | J7: Consumo público versus transferências nas contas nacionais. | K7: Prova Macroeconomia 2010.pdf — p. 5 — Q1 item 2
A8: 2010 | B8: 1 | C8: 3 | D8: V/F | E8: =IF(A8="","",TEXT(A8,"0")&"-Q"&TEXT(B8,"0")&"-"&IF(C8="","ABERTA",C8)) -> 2010-Q1-3 | F8: =IF(D8="V/F",1,IF(D8="Aberta/numérica",5,"")) -> 1 | G8: 01 — Contas Nacionais | H8: =IF(A8="","",IF(C8="",COUNTIFS($A$5:$A$1504,A8,$B$5:$B$1504,B8,$C$5:$C$1504,"",$D$5:$D$1504,D8),COUNTIFS($A$5:$A$1504,A8,$B$5:$B$1504,B8,$C$5:$C$1504,C8,$D$5:$D$1504,D8))) -> 1 | I8: =IF(OR(F8="",H8="",G8=""),"",F8/H8) -> 1 | J8: PIB nominal, PIB real e deflator. | K8: Prova Macroeconomia 2010.pdf — p. 5 — Q1 item 3
A9: 2010 | B9: 1 | C9: 4 | D9: V/F | E9: =IF(A9="","",TEXT(A9,"0")&"-Q"&TEXT(B9,"0")&"-"&IF(C9="","ABERTA",C9)) -> 2010-Q1-4 | F9: =IF(D9="V/F",1,IF(D9="Aberta/numérica",5,"")) -> 1 | G9: 01 — Contas Nacionais | H9: =IF(A9="","",IF(C9="",COUNTIFS($A$5:$A$1504,A9,$B$5:$B$1504,B9,$C$5:$C$1504,"",$D$5:$D$1504,D9),COUNTIFS($A$5:$A$1504,A9,$B$5:$B$1504,B9,$C$5:$C$1504,C9,$D$5:$D$1504,D9))) -> 1 | I9: =IF(OR(F9="",H9="",G9=""),"",F9/H9) -> 1 | J9: PIB, renda nacional líquida e depreciação. | K9: Prova Macroeconomia 2010.pdf — p. 5 — Q1 item 4
A10: 2010 | B10: 2 | C10: 0 | D10: V/F | E10: =IF(A10="","",TEXT(A10,"0")&"-Q"&TEXT(B10,"0")&"-"&IF(C10="","ABERTA",C10)) -> 2010-Q2-0 | F10: =IF(D10="V/F",1,IF(D10="Aberta/numérica",5,"")) -> 1 | G10: 05 — IS-LM | H10: =IF(A10="","",IF(C10="",COUNTIFS($A$5:$A$1504,A10,$B$5:$B$1504,B10,$C$5:$C$1504,"",$D$5:$D$1504,D10),COUNTIFS($A$5:$A$1504,A10,$B$5:$B$1504,B10,$C$5:$C$1504,C10,$D$5:$D$1504,D10))) -> 1 | I10: =IF(OR(F10="",H10="",G10=""),"",F10/H10) -> 1 | J10: IS-LM com meta de juros: choque de demanda por moeda. | K10: Prova Macroeconomia 2010.pdf — p. 6 — Q2 item 0
A11: 2010 | B11: 2 | C11: 1 | D11: V/F | E11: =IF(A11="","",TEXT(A11,"0")&"-Q"&TEXT(B11,"0")&"-"&IF(C11="","ABERTA",C11)) -> 2010-Q2-1 | F11: =IF(D11="V/F",1,IF(D11="Aberta/numérica",5,"")) -> 1 | G11: 05 — IS-LM | H11: =IF(A11="","",IF(C11="",COUNTIFS($A$5:$A$1504,A11,$B$5:$B$1504,B11,$C$5:$C$1504,"",$D$5:$D$1504,D11),COUNTIFS($A$5:$A$1504,A11,$B$5:$B$1504,B11,$C$5:$C$1504,C11,$D$5:$D$1504,D11))) -> 1 | I11: =IF(OR(F11="",H11="",G11=""),"",F11/H11) -> 1 | J11: IS-LM: escolha do instrumento e estabilização diante de choques. | K11: Prova Macroeconomia 2010.pdf — p. 6 — Q2 item 1
A12: 2010 | B12: 2 | C12: 2 | D12: V/F | E12: =IF(A12="","",TEXT(A12,"0")&"-Q"&TEXT(B12,"0")&"-"&IF(C12="","ABERTA",C12)) -> 2010-Q2-2 | F12: =IF(D12="V/F",1,IF(D12="Aberta/numérica",5,"")) -> 1 | G12: 05 — IS-LM | H12: =IF(A12="","",IF(C12="",COUNTIFS($A$5:$A$1504,A12,$B$5:$B$1504,B12,$C$5:$C$1504,"",$D$5:$D$1504,D12),COUNTIFS($A$5:$A$1504,A12,$B$5:$B$1504,B12,$C$5:$C$1504,C12,$D$5:$D$1504,D12))) -> 1 | I12: =IF(OR(F12="",H12="",G12=""),"",F12/H12) -> 1 | J12: Multiplicador fiscal com juros fixos versus moeda fixa. | K12: Prova Macroeconomia 2010.pdf — p. 6 — Q2 item 2
A13: 2010 | B13: 2 | C13: 3 | D13: V/F | E13: =IF(A13="","",TEXT(A13,"0")&"-Q"&TEXT(B13,"0")&"-"&IF(C13="","ABERTA",C13)) -> 2010-Q2-3 | F13: =IF(D13="V/F",1,IF(D13="Aberta/numérica",5,"")) -> 1 | G13: 05 — IS-LM | H13: =IF(A13="","",IF(C13="",COUNTIFS($A$5:$A$1504,A13,$B$5:$B$1504,B13,$C$5:$C$1504,"",$D$5:$D$1504,D13),COUNTIFS($A$5:$A$1504,A13,$B$5:$B$1504,B13,$C$5:$C$1504,C13,$D$5:$D$1504,D13))) -> 1 | I13: =IF(OR(F13="",H13="",G13=""),"",F13/H13) -> 1 | J13: Acomodação monetária para manter os juros no IS-LM. | K13: Prova Macroeconomia 2010.pdf — p. 6 — Q2 item 3
A14: 2010 | B14: 2 | C14: 4 | D14: V/F | E14: =IF(A14="","",TEXT(A14,"0")&"-Q"&TEXT(B14,"0")&"-"&IF(C14="","ABERTA",C14)) -> 2010-Q2-4 | F14: =IF(D14="V/F",1,IF(D14="Aberta/numérica",5,"")) -> 1 | G14: 03 — Sistema Monetário | H14: =IF(A14="","",IF(C14="",COUNTIFS($A$5:$A$1504,A14,$B$5:$B$1504,B14,$C$5:$C$1504,"",$D$5:$D$1504,D14),COUNTIFS($A$5:$A$1504,A14,$B$5:$B$1504,B14,$C$5:$C$1504,C14,$D$5:$D$1504,D14))) -> 1 | I14: =IF(OR(F14="",H14="",G14=""),"",F14/H14) -> 1 | J14: Composição de M1, multiplicador e compensação via mercado aberto. | K14: Prova Macroeconomia 2010.pdf — p. 6 — Q2 item 4
A15: 2010 | B15: 3 | C15: 0 | D15: V/F | E15: =IF(A15="","",TEXT(A15,"0")&"-Q"&TEXT(B15,"0")&"-"&IF(C15="","ABERTA",C15)) -> 2010-Q3-0 | F15: =IF(D15="V/F",1,IF(D15="Aberta/numérica",5,"")) -> 1 | G15: 01 — Contas Nacionais | H15: =IF(A15="","",IF(C15="",COUNTIFS($A$5:$A$1504,A15,$B$5:$B$1504,B15,$C$5:$C$1504,"",$D$5:$D$1504,D15),COUNTIFS($A$5:$A$1504,A15,$B$5:$B$1504,B15,$C$5:$C$1504,C15,$D$5:$D$1504,D15))) -> 1 | I15: =IF(OR(F15="",H15="",G15=""),"",F15/H15) -> 1 | J15: PIB real a preços constantes. | K15: Prova Macroeconomia 2010.pdf — p. 7 — Q3 item 0
A16: 2010 | B16: 3 | C16: 1 | D16: V/F | E16: =IF(A16="","",TEXT(A16,"0")&"-Q"&TEXT(B16,"0")&"-"&IF(C16="","ABERTA",C16)) -> 2010-Q3-1 | F16: =IF(D16="V/F",1,IF(D16="Aberta/numérica",5,"")) -> 1 | G16: 01 — Contas Nacionais | H16: =IF(A16="","",IF(C16="",COUNTIFS($A$5:$A$1504,A16,$B$5:$B$1504,B16,$C$5:$C$1504,"",$D$5:$D$1504,D16),COUNTIFS($A$5:$A$1504,A16,$B$5:$B$1504,B16,$C$5:$C$1504,C16,$D$5:$D$1504,D16))) -> 1 | I16: =IF(OR(F16="",H16="",G16=""),"",F16/H16) -> 1 | J16: Valoração da produção a preços do ano-base. | K16: Prova Macroeconomia 2010.pdf — p. 7 — Q3 item 1
... A60: 2010 | B60: 11 | C60: 4 | D60: V/F | E60: =IF(A60="","",TEXT(A60,"0")&"-Q"&TEXT(B60,"0")&"-"&IF(C60="","ABERTA",C60)) -> 2010-Q11-4 | F60: =IF(D60="V/F",1,IF(D60="Aberta/numérica",5,"")) -> 1 | G60: 11 — Crescimento Econômico | H60: =IF(A60="","",IF(C60="",COUNTIFS($A$5:$A$1504,A60,$B$5:$B$1504,B60,$C$5:$C$1504,"",$D$5:$D$1504,D60),COUNTIFS($A$5:$A$1504,A60,$B$5:$B$1504,B60,$C$5:$C$1504,C60,$D$5:$D$1504,D60))) -> 1 | I60: =IF(OR(F60="",H60="",G60=""),"",F60/H60) -> 1 | J60: Crescimento semiendógeno e trajetória equilibrada. | K60: Prova Macroeconomia 2010.pdf — p. 16 — Q11 item 4
A61: 2010 | B61: 12 | D61: Aberta/numérica | E61: =IF(A61="","",TEXT(A61,"0")&"-Q"&TEXT(B61,"0")&"-"&IF(C61="","ABERTA",C61)) -> 2010-Q12-ABERTA | F61: =IF(D61="V/F",1,IF(D61="Aberta/numérica",5,"")) -> 5 | G61: 07a — Paridades | H61: =IF(A61="","",IF(C61="",COUNTIFS($A$5:$A$1504,A61,$B$5:$B$1504,B61,$C$5:$C$1504,"",$D$5:$D$1504,D61),COUNTIFS($A$5:$A$1504,A61,$B$5:$B$1504,B61,$C$5:$C$1504,C61,$D$5:$D$1504,D61))) -> 1 | I61: =IF(OR(F61="",H61="",G61=""),"",F61/H61) -> 5 | J61: Paridade descoberta de juros e valor de resgate em moeda estrangeira. | K61: Prova Macroeconomia 2010.pdf — p. 17 — Q12 — Tipo B
A62: 2010 | B62: 13 | D62: Aberta/numérica | E62: =IF(A62="","",TEXT(A62,"0")&"-Q"&TEXT(B62,"0")&"-"&IF(C62="","ABERTA",C62)) -> 2010-Q13-ABERTA | F62: =IF(D62="V/F",1,IF(D62="Aberta/numérica",5,"")) -> 5 | G62: 07b — OA-DA | H62: =IF(A62="","",IF(C62="",COUNTIFS($A$5:$A$1504,A62,$B$5:$B$1504,B62,$C$5:$C$1504,"",$D$5:$D$1504,D62),COUNTIFS($A$5:$A$1504,A62,$B$5:$B$1504,B62,$C$5:$C$1504,C62,$D$5:$D$1504,D62))) -> 2 | I62: =IF(OR(F62="",H62="",G62=""),"",F62/H62) -> 2.5 | J62: Item misto: demanda agregada monetária, Phillips e lei de Okun. | K62: Prova Macroeconomia 2010.pdf — p. 18 — Q13 — Tipo B
A63: 2010 | B63: 13 | D63: Aberta/numérica | E63: =IF(A63="","",TEXT(A63,"0")&"-Q"&TEXT(B63,"0")&"-"&IF(C63="","ABERTA",C63)) -> 2010-Q13-ABERTA | F63: =IF(D63="V/F",1,IF(D63="Aberta/numérica",5,"")) -> 5 | G63: 08 — Curva de Phillips | H63: =IF(A63="","",IF(C63="",COUNTIFS($A$5:$A$1504,A63,$B$5:$B$1504,B63,$C$5:$C$1504,"",$D$5:$D$1504,D63),COUNTIFS($A$5:$A$1504,A63,$B$5:$B$1504,B63,$C$5:$C$1504,C63,$D$5:$D$1504,D63))) -> 2 | I63: =IF(OR(F63="",H63="",G63=""),"",F63/H63) -> 2.5 | J63: Item misto: demanda agregada monetária, Phillips e lei de Okun. | K63: Prova Macroeconomia 2010.pdf — p. 18 — Q13 — Tipo B
